Watching for file changes with StatReloader
Запрошена страница с корзиной пользователя
Запрошена страница с корзиной пользователя
Запрошена страница с корзиной пользователя
Запрошена страница с корзиной пользователя
Not Found: /favicon.ico
Запрошена страница с корзиной пользователя
Запрошена страница с корзиной пользователя
Запрошена страница с корзиной пользователя
Запрошена страница с корзиной пользователя
C:\Users\11\Desktop\java\python_django\16_LoggingAndProfiling\market\settings.py changed, reloading.
Watching for file changes with StatReloader
Запрошена страница с корзиной пользователя
Запрошена страница с корзиной пользователя
Watching for file changes with StatReloader
Запрошена страница с корзиной пользователя
Запрошена страница с корзиной пользователя
Not Found: /favicon.ico
Internal Server Error: /to_product/
Traceback (most recent call last):
  File "C:\Python39\lib\site-packages\django\core\handlers\exception.py", line 47, in inner
    response = get_response(request)
  File "C:\Python39\lib\site-packages\django\core\handlers\base.py", line 181, in _get_response
    response = wrapped_callback(request, *callback_args, **callback_kwargs)
  File "C:\Users\11\Desktop\java\python_django\16_LoggingAndProfiling\market\views.py", line 91, in to_product_profile
    product.category = random.randint(1, 7)
  File "C:\Python39\lib\site-packages\django\db\models\fields\related_descriptors.py", line 215, in __set__
    raise ValueError(
ValueError: Cannot assign "4": "ProductProfile.category" must be a "Category" instance.
Запрошена страница с корзиной пользователя
Запрошена страница с корзиной пользователя
C:\Users\11\Desktop\java\python_django\16_LoggingAndProfiling\market\views.py changed, reloading.
Watching for file changes with StatReloader
Internal Server Error: /to_product/
Traceback (most recent call last):
  File "C:\Python39\lib\site-packages\django\core\handlers\exception.py", line 47, in inner
    response = get_response(request)
  File "C:\Python39\lib\site-packages\django\core\handlers\base.py", line 181, in _get_response
    response = wrapped_callback(request, *callback_args, **callback_kwargs)
  File "C:\Users\11\Desktop\java\python_django\16_LoggingAndProfiling\market\views.py", line 91, in to_product_profile
    product.category = random.randint(1, 4)
  File "C:\Python39\lib\site-packages\django\db\models\fields\related_descriptors.py", line 215, in __set__
    raise ValueError(
ValueError: Cannot assign "3": "ProductProfile.category" must be a "Category" instance.
C:\Users\11\Desktop\java\python_django\16_LoggingAndProfiling\market\views.py changed, reloading.
Watching for file changes with StatReloader
Запрошена страница с корзиной пользователя
Запрошена страница с корзиной пользователя
C:\Users\11\Desktop\java\python_django\16_LoggingAndProfiling\market\views.py changed, reloading.
Watching for file changes with StatReloader
Watching for file changes with StatReloader
C:\Users\11\Desktop\java\python_django\16_LoggingAndProfiling\market\views.py changed, reloading.
Watching for file changes with StatReloader
Internal Server Error: /to_product/
Traceback (most recent call last):
  File "C:\Python39\lib\site-packages\django\core\handlers\exception.py", line 47, in inner
    response = get_response(request)
  File "C:\Python39\lib\site-packages\django\core\handlers\base.py", line 181, in _get_response
    response = wrapped_callback(request, *callback_args, **callback_kwargs)
  File "C:\Users\11\Desktop\java\python_django\16_LoggingAndProfiling\market\views.py", line 91, in to_product_profile
    product.category = "TestCategory" + str(random.randint(1, 30))
  File "C:\Python39\lib\site-packages\django\db\models\fields\related_descriptors.py", line 215, in __set__
    raise ValueError(
ValueError: Cannot assign "'TestCategory17'": "ProductProfile.category" must be a "Category" instance.
Watching for file changes with StatReloader
Internal Server Error: /to_product/
Traceback (most recent call last):
  File "C:\Python39\lib\site-packages\django\core\handlers\exception.py", line 47, in inner
    response = get_response(request)
  File "C:\Python39\lib\site-packages\django\core\handlers\base.py", line 181, in _get_response
    response = wrapped_callback(request, *callback_args, **callback_kwargs)
  File "C:\Users\11\Desktop\java\python_django\16_LoggingAndProfiling\market\views.py", line 91, in to_product_profile
    product.category = Category.objects.get(name="TestCategory" + str(random.randint(1, 30)))
  File "C:\Python39\lib\site-packages\django\db\models\manager.py", line 85, in manager_method
    return getattr(self.get_queryset(), name)(*args, **kwargs)
  File "C:\Python39\lib\site-packages\django\db\models\query.py", line 439, in get
    raise self.model.DoesNotExist(
app_shops.models.Category.DoesNotExist: Category matching query does not exist.
C:\Users\11\Desktop\java\python_django\16_LoggingAndProfiling\market\views.py changed, reloading.
Watching for file changes with StatReloader
Internal Server Error: /to_product/
Traceback (most recent call last):
  File "C:\Python39\lib\site-packages\django\core\handlers\exception.py", line 47, in inner
    response = get_response(request)
  File "C:\Python39\lib\site-packages\django\core\handlers\base.py", line 181, in _get_response
    response = wrapped_callback(request, *callback_args, **callback_kwargs)
  File "C:\Users\11\Desktop\java\python_django\16_LoggingAndProfiling\market\views.py", line 92, in to_product_profile
    product.category = Category.objects.get(name=category_name)
  File "C:\Python39\lib\site-packages\django\db\models\manager.py", line 85, in manager_method
    return getattr(self.get_queryset(), name)(*args, **kwargs)
  File "C:\Python39\lib\site-packages\django\db\models\query.py", line 439, in get
    raise self.model.DoesNotExist(
app_shops.models.Category.DoesNotExist: Category matching query does not exist.
Internal Server Error: /to_product/
Traceback (most recent call last):
  File "C:\Python39\lib\site-packages\django\core\handlers\exception.py", line 47, in inner
    response = get_response(request)
  File "C:\Python39\lib\site-packages\django\core\handlers\base.py", line 181, in _get_response
    response = wrapped_callback(request, *callback_args, **callback_kwargs)
  File "C:\Users\11\Desktop\java\python_django\16_LoggingAndProfiling\market\views.py", line 92, in to_product_profile
    product.category = Category.objects.get(name=category_name)
  File "C:\Python39\lib\site-packages\django\db\models\manager.py", line 85, in manager_method
    return getattr(self.get_queryset(), name)(*args, **kwargs)
  File "C:\Python39\lib\site-packages\django\db\models\query.py", line 439, in get
    raise self.model.DoesNotExist(
app_shops.models.Category.DoesNotExist: Category matching query does not exist.
Запрошена страница с корзиной пользователя
Запрошена страница с корзиной пользователя
Internal Server Error: /to_product/
Traceback (most recent call last):
  File "C:\Python39\lib\site-packages\django\core\handlers\exception.py", line 47, in inner
    response = get_response(request)
  File "C:\Python39\lib\site-packages\django\core\handlers\base.py", line 181, in _get_response
    response = wrapped_callback(request, *callback_args, **callback_kwargs)
  File "C:\Users\11\Desktop\java\python_django\16_LoggingAndProfiling\market\views.py", line 92, in to_product_profile
    product.category = Category.objects.get(name=category_name)
  File "C:\Python39\lib\site-packages\django\db\models\manager.py", line 85, in manager_method
    return getattr(self.get_queryset(), name)(*args, **kwargs)
  File "C:\Python39\lib\site-packages\django\db\models\query.py", line 439, in get
    raise self.model.DoesNotExist(
app_shops.models.Category.DoesNotExist: Category matching query does not exist.
Internal Server Error: /to_product/
Traceback (most recent call last):
  File "C:\Python39\lib\site-packages\django\core\handlers\exception.py", line 47, in inner
    response = get_response(request)
  File "C:\Python39\lib\site-packages\django\core\handlers\base.py", line 181, in _get_response
    response = wrapped_callback(request, *callback_args, **callback_kwargs)
  File "C:\Users\11\Desktop\java\python_django\16_LoggingAndProfiling\market\views.py", line 92, in to_product_profile
    product.category = Category.objects.get(name=category_name)
  File "C:\Python39\lib\site-packages\django\db\models\manager.py", line 85, in manager_method
    return getattr(self.get_queryset(), name)(*args, **kwargs)
  File "C:\Python39\lib\site-packages\django\db\models\query.py", line 439, in get
    raise self.model.DoesNotExist(
app_shops.models.Category.DoesNotExist: Category matching query does not exist.
C:\Users\11\Desktop\java\python_django\16_LoggingAndProfiling\market\views.py changed, reloading.
Watching for file changes with StatReloader
Запрошена страница с корзиной пользователя
Запрошена страница с корзиной пользователя
Запрошена страница с корзиной пользователя
Запрошена страница с корзиной пользователя
Запрошена страница с корзиной пользователя
Запрошена страница с корзиной пользователя
Запрошена страница с корзиной пользователя
Запрошена страница с корзиной пользователя
Запрошена страница с корзиной пользователя
Запрошена страница с корзиной пользователя
Запрошена страница с корзиной пользователя
Запрошена страница с корзиной пользователя
Запрошена страница с корзиной пользователя
Запрошена страница с корзиной пользователя
Запрошена страница с корзиной пользователя
Запрошена страница с корзиной пользователя
Запрошена страница с корзиной пользователя
Запрошена страница с корзиной пользователя
Запрошена страница с корзиной пользователя
Запрошена страница с корзиной пользователя
Watching for file changes with StatReloader
Запрошена страница с корзиной пользователя
Запрошена страница с корзиной пользователя
Watching for file changes with StatReloader
Запрошена страница с корзиной пользователя
Запрошена страница с корзиной пользователя
C:\Users\11\Desktop\java\python_django\16_LoggingAndProfiling\market\views.py changed, reloading.
Watching for file changes with StatReloader
Watching for file changes with StatReloader
Запрошена страница с корзиной пользователя
Запрошена страница с корзиной пользователя
Internal Server Error: /shops/product_list
Traceback (most recent call last):
  File "C:\Python39\lib\site-packages\django\core\handlers\exception.py", line 47, in inner
    response = get_response(request)
  File "C:\Python39\lib\site-packages\django\core\handlers\base.py", line 188, in _get_response
    self.check_response(response, callback)
  File "C:\Python39\lib\site-packages\django\core\handlers\base.py", line 314, in check_response
    raise ValueError(
ValueError: The view app_shops.views.product_list_select_related didn't return an HttpResponse object. It returned an unawaited coroutine instead. You may need to add an 'await' into your view.
Watching for file changes with StatReloader
Internal Server Error: /shops/product_list
Traceback (most recent call last):
  File "C:\Python39\lib\site-packages\django\core\handlers\exception.py", line 47, in inner
    response = get_response(request)
  File "C:\Python39\lib\site-packages\django\core\handlers\base.py", line 188, in _get_response
    self.check_response(response, callback)
  File "C:\Python39\lib\site-packages\django\core\handlers\base.py", line 314, in check_response
    raise ValueError(
ValueError: The view app_shops.views.product_list_select_related didn't return an HttpResponse object. It returned an unawaited coroutine instead. You may need to add an 'await' into your view.
C:\Users\11\Desktop\java\python_django\16_LoggingAndProfiling\app_shops\views.py changed, reloading.
Watching for file changes with StatReloader
Запрошена страница с корзиной пользователя
Запрошена страница с корзиной пользователя
Запрошена страница с корзиной пользователя
Запрошена страница с корзиной пользователя
Запрошена страница с корзиной пользователя
Запрошена страница с корзиной пользователя
Запрошена страница с корзиной пользователя
Запрошена страница с корзиной пользователя
Запрошена страница с корзиной пользователя
Запрошена страница с корзиной пользователя
Запрошена страница с корзиной пользователя
Запрошена страница с корзиной пользователя
Запрошена страница с корзиной пользователя
Запрошена страница с корзиной пользователя
C:\Users\11\Desktop\java\python_django\16_LoggingAndProfiling\market\views.py changed, reloading.
Watching for file changes with StatReloader
Запрошена страница с корзиной пользователя
Запрошена страница с корзиной пользователя
Запрошена страница с корзиной пользователя
Запрошена страница с корзиной пользователя
Watching for file changes with StatReloader
Запрошена страница с корзиной пользователя
Запрошена страница с корзиной пользователя
Запрошена страница с корзиной пользователя
Watching for file changes with StatReloader
Watching for file changes with StatReloader
Not Found: /users/purchase_history/
Запрошена страница с корзиной пользователя
Запрошена страница с корзиной пользователя
Запрошена страница с корзиной пользователя
C:\Users\11\Desktop\java\python_django\16_LoggingAndProfiling\app_users\views.py changed, reloading.
Watching for file changes with StatReloader
Запрошена страница с корзиной пользователя
C:\Users\11\Desktop\java\python_django\16_LoggingAndProfiling\app_users\views.py changed, reloading.
Watching for file changes with StatReloader
Запрошена страница с корзиной пользователя
C:\Users\11\Desktop\java\python_django\16_LoggingAndProfiling\app_users\views.py changed, reloading.
Watching for file changes with StatReloader
Запрошена страница с корзиной пользователя
C:\Users\11\Desktop\java\python_django\16_LoggingAndProfiling\app_users\views.py changed, reloading.
Watching for file changes with StatReloader
Запрошена страница с корзиной пользователя
C:\Users\11\Desktop\java\python_django\16_LoggingAndProfiling\app_users\views.py changed, reloading.
Watching for file changes with StatReloader
C:\Users\11\Desktop\java\python_django\16_LoggingAndProfiling\app_users\views.py changed, reloading.
Watching for file changes with StatReloader
Запрошена страница с корзиной пользователя
C:\Users\11\Desktop\java\python_django\16_LoggingAndProfiling\app_users\views.py changed, reloading.
Watching for file changes with StatReloader
Запрошена страница с корзиной пользователя
Запрошена страница с корзиной пользователя
Запрошена страница с корзиной пользователя
Запрошена страница с корзиной пользователя
Запрошена страница с корзиной пользователя
C:\Users\11\Desktop\java\python_django\16_LoggingAndProfiling\app_users\views.py changed, reloading.
Watching for file changes with StatReloader
Запрошена страница с корзиной пользователя
Запрошена страница с корзиной пользователя
Запрошена страница с корзиной пользователя
Запрошена страница с корзиной пользователя
Запрошена страница с корзиной пользователя
Запрошена страница с корзиной пользователя
Запрошена страница с корзиной пользователя
Запрошена страница с корзиной пользователя
Запрошена страница с корзиной пользователя
Запрошена страница с корзиной пользователя
C:\Users\11\Desktop\java\python_django\16_LoggingAndProfiling\app_users\views.py changed, reloading.
Watching for file changes with StatReloader
Запрошена страница с корзиной пользователя
Запрошена страница с корзиной пользователя
Запрошена страница с корзиной пользователя
Запрошена страница с корзиной пользователя
C:\Users\11\Desktop\java\python_django\16_LoggingAndProfiling\app_users\views.py changed, reloading.
Watching for file changes with StatReloader
C:\Users\11\Desktop\java\python_django\16_LoggingAndProfiling\app_users\views.py changed, reloading.
Watching for file changes with StatReloader
Запрошена страница с корзиной пользователя
Запрошена страница с корзиной пользователя
Запрошена страница с корзиной пользователя
Запрошена страница с корзиной пользователя
Запрошена страница с корзиной пользователя
Запрошена страница с корзиной пользователя
Запрошена страница с корзиной пользователя
Запрошена страница с корзиной пользователя
Запрошена страница с корзиной пользователя
Запрошена страница с корзиной пользователя
C:\Users\11\Desktop\java\python_django\16_LoggingAndProfiling\app_users\views.py changed, reloading.
Watching for file changes with StatReloader
Запрошена страница с корзиной пользователя
Запрошена страница с корзиной пользователя
Запрошена страница с корзиной пользователя
Запрошена страница с корзиной пользователя
C:\Users\11\Desktop\java\python_django\16_LoggingAndProfiling\app_users\views.py changed, reloading.
Watching for file changes with StatReloader
Запрошена страница с корзиной пользователя
Запрошена страница с корзиной пользователя
Запрошена страница с корзиной пользователя
C:\Users\11\Desktop\java\python_django\16_LoggingAndProfiling\app_users\views.py changed, reloading.
Watching for file changes with StatReloader
Запрошена страница с корзиной пользователя
C:\Users\11\Desktop\java\python_django\16_LoggingAndProfiling\app_users\views.py changed, reloading.
Watching for file changes with StatReloader
Запрошена страница с корзиной пользователя
Запрошена страница с корзиной пользователя
Запрошена страница с корзиной пользователя
Запрошена страница с корзиной пользователя
Запрошена страница с корзиной пользователя
Запрошена страница с корзиной пользователя
Запрошена страница с корзиной пользователя
Запрошена страница с корзиной пользователя
Запрошена страница с корзиной пользователя
C:\Users\11\Desktop\java\python_django\16_LoggingAndProfiling\app_users\views.py changed, reloading.
Watching for file changes with StatReloader
Запрошена страница с корзиной пользователя
Запрошена страница с корзиной пользователя
Запрошена страница с корзиной пользователя
Not Found: /favicon.ico
C:\Users\11\Desktop\java\python_django\16_LoggingAndProfiling\app_users\views.py changed, reloading.
Watching for file changes with StatReloader
Запрошена страница с корзиной пользователя
Запрошена страница с корзиной пользователя
Запрошена страница с корзиной пользователя
C:\Users\11\Desktop\java\python_django\16_LoggingAndProfiling\app_users\views.py changed, reloading.
Watching for file changes with StatReloader
Запрошена страница с корзиной пользователя
Запрошена страница с корзиной пользователя
Запрошена страница с корзиной пользователя
Запрошена страница с корзиной пользователя
C:\Users\11\Desktop\java\python_django\16_LoggingAndProfiling\app_users\views.py changed, reloading.
Watching for file changes with StatReloader
Запрошена страница с корзиной пользователя
Запрошена страница с корзиной пользователя
Запрошена страница с корзиной пользователя
Запрошена страница с корзиной пользователя
C:\Users\11\Desktop\java\python_django\16_LoggingAndProfiling\app_users\views.py changed, reloading.
Watching for file changes with StatReloader
Запрошена страница с корзиной пользователя
Запрошена страница с корзиной пользователя
Запрошена страница с корзиной пользователя
Not Found: /users/purchase_history/
C:\Users\11\Desktop\java\python_django\16_LoggingAndProfiling\market\views.py changed, reloading.
Watching for file changes with StatReloader
Запрошена страница с корзиной пользователя
C:\Users\11\Desktop\java\python_django\16_LoggingAndProfiling\market\views.py changed, reloading.
Watching for file changes with StatReloader
Запрошена страница с корзиной пользователя
C:\Users\11\Desktop\java\python_django\16_LoggingAndProfiling\market\views.py changed, reloading.
Watching for file changes with StatReloader
Запрошена страница с корзиной пользователя
C:\Users\11\Desktop\java\python_django\16_LoggingAndProfiling\app_users\views.py changed, reloading.
Watching for file changes with StatReloader
Запрошена страница с корзиной пользователя
Запрошена страница с корзиной пользователя
Запрошена страница с корзиной пользователя
C:\Users\11\Desktop\java\python_django\16_LoggingAndProfiling\app_users\views.py changed, reloading.
Watching for file changes with StatReloader
Запрошена страница с корзиной пользователя
Запрошена страница с корзиной пользователя
Запрошена страница с корзиной пользователя
Запрошена страница с корзиной пользователя
Запрошена страница с корзиной пользователя
Запрошена страница с корзиной пользователя
Запрошена страница с корзиной пользователя
Запрошена страница с корзиной пользователя
Запрошена страница с корзиной пользователя
Запрошена страница с корзиной пользователя
Запрошена страница с корзиной пользователя
Запрошена страница с корзиной пользователя
Internal Server Error: /shops/32/category/6/product/157
Traceback (most recent call last):
  File "C:\Python39\lib\site-packages\django\core\handlers\exception.py", line 47, in inner
    response = get_response(request)
  File "C:\Python39\lib\site-packages\django\core\handlers\base.py", line 181, in _get_response
    response = wrapped_callback(request, *callback_args, **callback_kwargs)
  File "C:\Python39\lib\site-packages\django\views\generic\base.py", line 69, in view
    return self.dispatch(request, *args, **kwargs)
  File "C:\Python39\lib\site-packages\django\views\generic\base.py", line 101, in dispatch
    return handler(request, *args, **kwargs)
  File "C:\Users\11\Desktop\java\python_django\16_LoggingAndProfiling\app_shops\views.py", line 251, in post
    user_name = self.extra_context['user'].username  # request.user.username
TypeError: 'NoneType' object is not subscriptable
C:\Users\11\Desktop\java\python_django\16_LoggingAndProfiling\app_shops\views.py changed, reloading.
Watching for file changes with StatReloader
Internal Server Error: /shops/32/category/6/product/82
Traceback (most recent call last):
  File "C:\Python39\lib\site-packages\django\core\handlers\exception.py", line 47, in inner
    response = get_response(request)
  File "C:\Python39\lib\site-packages\django\core\handlers\base.py", line 181, in _get_response
    response = wrapped_callback(request, *callback_args, **callback_kwargs)
  File "C:\Python39\lib\site-packages\django\views\generic\base.py", line 69, in view
    return self.dispatch(request, *args, **kwargs)
  File "C:\Python39\lib\site-packages\django\views\generic\base.py", line 101, in dispatch
    return handler(request, *args, **kwargs)
  File "C:\Users\11\Desktop\java\python_django\16_LoggingAndProfiling\app_shops\views.py", line 251, in post
    user_name = self.extra_context['user_profile'].username  # request.user.username
TypeError: 'NoneType' object is not subscriptable
C:\Users\11\Desktop\java\python_django\16_LoggingAndProfiling\app_shops\views.py changed, reloading.
Watching for file changes with StatReloader
C:\Users\11\Desktop\java\python_django\16_LoggingAndProfiling\app_shops\views.py changed, reloading.
Watching for file changes with StatReloader
Internal Server Error: /shops/32/category/6/product/82
Traceback (most recent call last):
  File "C:\Python39\lib\site-packages\django\core\handlers\exception.py", line 47, in inner
    response = get_response(request)
  File "C:\Python39\lib\site-packages\django\core\handlers\base.py", line 181, in _get_response
    response = wrapped_callback(request, *callback_args, **callback_kwargs)
  File "C:\Python39\lib\site-packages\django\views\generic\base.py", line 69, in view
    return self.dispatch(request, *args, **kwargs)
  File "C:\Python39\lib\site-packages\django\views\generic\base.py", line 101, in dispatch
    return handler(request, *args, **kwargs)
  File "C:\Users\11\Desktop\java\python_django\16_LoggingAndProfiling\app_shops\views.py", line 252, in post
    print(self.extra_context['user_profile'])
TypeError: 'NoneType' object is not subscriptable
C:\Users\11\Desktop\java\python_django\16_LoggingAndProfiling\app_shops\views.py changed, reloading.
Watching for file changes with StatReloader
Запрошена страница с корзиной пользователя
Запрошена страница с корзиной пользователя
C:\Users\11\Desktop\java\python_django\16_LoggingAndProfiling\app_shops\views.py changed, reloading.
Watching for file changes with StatReloader
Запрошена страница с корзиной пользователя
Запрошена страница с корзиной пользователя
C:\Users\11\Desktop\java\python_django\16_LoggingAndProfiling\app_shops\views.py changed, reloading.
Watching for file changes with StatReloader
C:\Users\11\Desktop\java\python_django\16_LoggingAndProfiling\app_shops\views.py changed, reloading.
Watching for file changes with StatReloader
Запрошена страница с корзиной пользователя
C:\Users\11\Desktop\java\python_django\16_LoggingAndProfiling\app_shops\views.py changed, reloading.
Watching for file changes with StatReloader
C:\Users\11\Desktop\java\python_django\16_LoggingAndProfiling\app_shops\views.py changed, reloading.
Watching for file changes with StatReloader
Запрошена страница с корзиной пользователя
Internal Server Error: /shops/32/category/6
Traceback (most recent call last):
  File "C:\Python39\lib\site-packages\django\core\handlers\exception.py", line 47, in inner
    response = get_response(request)
  File "C:\Python39\lib\site-packages\django\core\handlers\base.py", line 181, in _get_response
    response = wrapped_callback(request, *callback_args, **callback_kwargs)
  File "C:\Python39\lib\site-packages\django\views\generic\base.py", line 69, in view
    return self.dispatch(request, *args, **kwargs)
  File "C:\Python39\lib\site-packages\django\views\generic\base.py", line 101, in dispatch
    return handler(request, *args, **kwargs)
  File "C:\Users\11\Desktop\java\python_django\16_LoggingAndProfiling\app_shops\views.py", line 140, in get
    return super().get(*args, **kwargs)
  File "C:\Python39\lib\site-packages\django\views\generic\list.py", line 142, in get
    self.object_list = self.get_queryset()
  File "C:\Python39\lib\site-packages\django\views\generic\list.py", line 35, in get_queryset
    raise ImproperlyConfigured(
django.core.exceptions.ImproperlyConfigured: ProductListVew is missing a QuerySet. Define ProductListVew.model, ProductListVew.queryset, or override ProductListVew.get_queryset().
Watching for file changes with StatReloader
Internal Server Error: /shops/32/category/6
Traceback (most recent call last):
  File "C:\Python39\lib\site-packages\django\core\handlers\exception.py", line 47, in inner
    response = get_response(request)
  File "C:\Python39\lib\site-packages\django\core\handlers\base.py", line 181, in _get_response
    response = wrapped_callback(request, *callback_args, **callback_kwargs)
TypeError: product_list() got an unexpected keyword argument 'pk'
Запрошена страница с корзиной пользователя
Запрошена страница с корзиной пользователя
Internal Server Error: /shops/2/category/3
Traceback (most recent call last):
  File "C:\Python39\lib\site-packages\django\core\handlers\exception.py", line 47, in inner
    response = get_response(request)
  File "C:\Python39\lib\site-packages\django\core\handlers\base.py", line 181, in _get_response
    response = wrapped_callback(request, *callback_args, **callback_kwargs)
TypeError: product_list() got an unexpected keyword argument 'pk'
Запрошена страница с корзиной пользователя
Запрошена страница с корзиной пользователя
Запрошена страница с корзиной пользователя
Запрошена страница с корзиной пользователя
Internal Server Error: /shops/2/category/4
Traceback (most recent call last):
  File "C:\Python39\lib\site-packages\django\core\handlers\exception.py", line 47, in inner
    response = get_response(request)
  File "C:\Python39\lib\site-packages\django\core\handlers\base.py", line 181, in _get_response
    response = wrapped_callback(request, *callback_args, **callback_kwargs)
TypeError: product_list() got an unexpected keyword argument 'pk'
Internal Server Error: /shops/2/category/3
Traceback (most recent call last):
  File "C:\Python39\lib\site-packages\django\core\handlers\exception.py", line 47, in inner
    response = get_response(request)
  File "C:\Python39\lib\site-packages\django\core\handlers\base.py", line 181, in _get_response
    response = wrapped_callback(request, *callback_args, **callback_kwargs)
TypeError: product_list() got an unexpected keyword argument 'pk'
Watching for file changes with StatReloader
Запрошена страница с корзиной пользователя
Запрошена страница с корзиной пользователя
Запрошена страница с корзиной пользователя
Запрошена страница с корзиной пользователя
Запрошена страница с корзиной пользователя
Запрошена страница с корзиной пользователя
Запрошена страница с корзиной пользователя
Запрошена страница с корзиной пользователя
Запрошена страница с корзиной пользователя
Запрошена страница с корзиной пользователя
Запрошена страница с корзиной пользователя
C:\Users\11\Desktop\java\python_django\16_LoggingAndProfiling\app_shops\views.py changed, reloading.
Watching for file changes with StatReloader
Запрошена страница с корзиной пользователя
Запрошена страница с корзиной пользователя
Запрошена страница с корзиной пользователя
C:\Users\11\Desktop\java\python_django\16_LoggingAndProfiling\app_shops\views.py changed, reloading.
Watching for file changes with StatReloader
Watching for file changes with StatReloader
Запрошена страница с корзиной пользователя
C:\Users\11\Desktop\java\python_django\16_LoggingAndProfiling\app_shops\views.py changed, reloading.
Watching for file changes with StatReloader
C:\Users\11\Desktop\java\python_django\16_LoggingAndProfiling\app_shops\views.py changed, reloading.
Watching for file changes with StatReloader
Запрошена страница с корзиной пользователя
Запрошена страница с корзиной пользователя
Запрошена страница с корзиной пользователя
Запрошена страница с корзиной пользователя
Запрошена страница с корзиной пользователя
Internal Server Error: /shops/check
Traceback (most recent call last):
  File "C:\Python39\lib\site-packages\django\core\handlers\exception.py", line 47, in inner
    response = get_response(request)
  File "C:\Python39\lib\site-packages\django\core\handlers\base.py", line 181, in _get_response
    response = wrapped_callback(request, *callback_args, **callback_kwargs)
  File "C:\Users\11\Desktop\java\python_django\16_LoggingAndProfiling\app_shops\views.py", line 62, in check_payment
    if extra_context['profile'].purchases_count >= new_sum:  # request.user.profile
AttributeError: 'str' object has no attribute 'purchases_count'
C:\Users\11\Desktop\java\python_django\16_LoggingAndProfiling\app_shops\views.py changed, reloading.
Watching for file changes with StatReloader
Запрошена страница с корзиной пользователя
Internal Server Error: /shops/check
Traceback (most recent call last):
  File "C:\Python39\lib\site-packages\django\core\handlers\exception.py", line 47, in inner
    response = get_response(request)
  File "C:\Python39\lib\site-packages\django\core\handlers\base.py", line 181, in _get_response
    response = wrapped_callback(request, *callback_args, **callback_kwargs)
  File "C:\Users\11\Desktop\java\python_django\16_LoggingAndProfiling\app_shops\views.py", line 70, in check_payment
    obj_basket.user = extra_context['user']  # user # Profile.objects.get(user=request.user)
  File "C:\Python39\lib\site-packages\django\db\models\fields\related_descriptors.py", line 215, in __set__
    raise ValueError(
ValueError: Cannot assign "<User: pavlove>": "UserBasket.user" must be a "Profile" instance.
C:\Users\11\Desktop\java\python_django\16_LoggingAndProfiling\app_shops\views.py changed, reloading.
Watching for file changes with StatReloader
Запрошена страница с корзиной пользователя
Internal Server Error: /shops/check
Traceback (most recent call last):
  File "C:\Python39\lib\site-packages\django\core\handlers\exception.py", line 47, in inner
    response = get_response(request)
  File "C:\Python39\lib\site-packages\django\core\handlers\base.py", line 181, in _get_response
    response = wrapped_callback(request, *callback_args, **callback_kwargs)
  File "C:\Users\11\Desktop\java\python_django\16_LoggingAndProfiling\app_shops\views.py", line 70, in check_payment
    obj_basket.user = extra_context['user'].username  # user # Profile.objects.get(user=request.user)
  File "C:\Python39\lib\site-packages\django\db\models\fields\related_descriptors.py", line 215, in __set__
    raise ValueError(
ValueError: Cannot assign "'pavlove'": "UserBasket.user" must be a "Profile" instance.
C:\Users\11\Desktop\java\python_django\16_LoggingAndProfiling\app_shops\views.py changed, reloading.
Watching for file changes with StatReloader
C:\Users\11\Desktop\java\python_django\16_LoggingAndProfiling\app_shops\views.py changed, reloading.
Watching for file changes with StatReloader
Запрошена страница с корзиной пользователя
Internal Server Error: /shops/check
Traceback (most recent call last):
  File "C:\Python39\lib\site-packages\django\core\handlers\exception.py", line 47, in inner
    response = get_response(request)
  File "C:\Python39\lib\site-packages\django\core\handlers\base.py", line 181, in _get_response
    response = wrapped_callback(request, *callback_args, **callback_kwargs)
  File "C:\Users\11\Desktop\java\python_django\16_LoggingAndProfiling\app_shops\views.py", line 79, in check_payment
    f' {round(extra_context["profile"].purchases_count, 2)}'  # Profile.objects.get(user=request.user)
AttributeError: 'str' object has no attribute 'purchases_count'
C:\Users\11\Desktop\java\python_django\16_LoggingAndProfiling\app_shops\views.py changed, reloading.
Watching for file changes with StatReloader
Запрошена страница с корзиной пользователя
Запрошена страница с корзиной пользователя
Запрошена страница с корзиной пользователя
C:\Users\11\Desktop\java\python_django\16_LoggingAndProfiling\app_shops\views.py changed, reloading.
Watching for file changes with StatReloader
Watching for file changes with StatReloader
Watching for file changes with StatReloader
Запрошена страница с корзиной пользователя
Not Found: /favicon.ico
Internal Server Error: /admin/app_shops/productinshop/
Traceback (most recent call last):
  File "C:\Python39\lib\site-packages\django\core\handlers\exception.py", line 47, in inner
    response = get_response(request)
  File "C:\Python39\lib\site-packages\django\core\handlers\base.py", line 181, in _get_response
    response = wrapped_callback(request, *callback_args, **callback_kwargs)
  File "C:\Python39\lib\site-packages\django\contrib\admin\options.py", line 622, in wrapper
    return self.admin_site.admin_view(view)(*args, **kwargs)
  File "C:\Python39\lib\site-packages\django\utils\decorators.py", line 130, in _wrapped_view
    response = view_func(request, *args, **kwargs)
  File "C:\Python39\lib\site-packages\django\views\decorators\cache.py", line 57, in _wrapped_view_func
    response = view_func(request, *args, **kwargs)
  File "C:\Python39\lib\site-packages\django\contrib\admin\sites.py", line 236, in inner
    return view(request, *args, **kwargs)
  File "C:\Python39\lib\site-packages\django\utils\decorators.py", line 43, in _wrapper
    return bound_method(*args, **kwargs)
  File "C:\Python39\lib\site-packages\django\utils\decorators.py", line 130, in _wrapped_view
    response = view_func(request, *args, **kwargs)
  File "C:\Python39\lib\site-packages\django\contrib\admin\options.py", line 1710, in changelist_view
    cl = self.get_changelist_instance(request)
  File "C:\Python39\lib\site-packages\django\contrib\admin\options.py", line 742, in get_changelist_instance
    return ChangeList(
  File "C:\Python39\lib\site-packages\django\contrib\admin\views\main.py", line 100, in __init__
    self.queryset = self.get_queryset(request)
  File "C:\Python39\lib\site-packages\django\contrib\admin\views\main.py", line 486, in get_queryset
    qs, search_may_have_duplicates = self.model_admin.get_search_results(
  File "C:\Python39\lib\site-packages\django\contrib\admin\options.py", line 1041, in get_search_results
    queryset = queryset.filter(or_queries)
  File "C:\Python39\lib\site-packages\django\db\models\query.py", line 974, in filter
    return self._filter_or_exclude(False, args, kwargs)
  File "C:\Python39\lib\site-packages\django\db\models\query.py", line 992, in _filter_or_exclude
    clone._filter_or_exclude_inplace(negate, args, kwargs)
  File "C:\Python39\lib\site-packages\django\db\models\query.py", line 999, in _filter_or_exclude_inplace
    self._query.add_q(Q(*args, **kwargs))
  File "C:\Python39\lib\site-packages\django\db\models\sql\query.py", line 1375, in add_q
    clause, _ = self._add_q(q_object, self.used_aliases)
  File "C:\Python39\lib\site-packages\django\db\models\sql\query.py", line 1396, in _add_q
    child_clause, needed_inner = self.build_filter(
  File "C:\Python39\lib\site-packages\django\db\models\sql\query.py", line 1252, in build_filter
    return self._add_q(
  File "C:\Python39\lib\site-packages\django\db\models\sql\query.py", line 1396, in _add_q
    child_clause, needed_inner = self.build_filter(
  File "C:\Python39\lib\site-packages\django\db\models\sql\query.py", line 1329, in build_filter
    condition = self.build_lookup(lookups, col, value)
  File "C:\Python39\lib\site-packages\django\db\models\sql\query.py", line 1171, in build_lookup
    raise FieldError('Related Field got invalid lookup: {}'.format(lookup_name))
django.core.exceptions.FieldError: Related Field got invalid lookup: icontains
Internal Server Error: /admin/app_shops/productinshop/add/
Traceback (most recent call last):
  File "C:\Python39\lib\site-packages\django\core\handlers\exception.py", line 47, in inner
    response = get_response(request)
  File "C:\Python39\lib\site-packages\django\core\handlers\base.py", line 181, in _get_response
    response = wrapped_callback(request, *callback_args, **callback_kwargs)
  File "C:\Python39\lib\site-packages\django\contrib\admin\options.py", line 622, in wrapper
    return self.admin_site.admin_view(view)(*args, **kwargs)
  File "C:\Python39\lib\site-packages\django\utils\decorators.py", line 130, in _wrapped_view
    response = view_func(request, *args, **kwargs)
  File "C:\Python39\lib\site-packages\django\views\decorators\cache.py", line 57, in _wrapped_view_func
    response = view_func(request, *args, **kwargs)
  File "C:\Python39\lib\site-packages\django\contrib\admin\sites.py", line 236, in inner
    return view(request, *args, **kwargs)
  File "C:\Python39\lib\site-packages\django\contrib\admin\options.py", line 1670, in add_view
    return self.changeform_view(request, None, form_url, extra_context)
  File "C:\Python39\lib\site-packages\django\utils\decorators.py", line 43, in _wrapper
    return bound_method(*args, **kwargs)
  File "C:\Python39\lib\site-packages\django\utils\decorators.py", line 130, in _wrapped_view
    response = view_func(request, *args, **kwargs)
  File "C:\Python39\lib\site-packages\django\contrib\admin\options.py", line 1549, in changeform_view
    return self._changeform_view(request, object_id, form_url, extra_context)
  File "C:\Python39\lib\site-packages\django\contrib\admin\options.py", line 1599, in _changeform_view
    self.save_model(request, new_object, form, not add)
  File "C:\Python39\lib\site-packages\django\contrib\admin\options.py", line 1108, in save_model
    obj.save()
  File "C:\Users\11\Desktop\java\python_django\16_LoggingAndProfiling\app_shops\models.py", line 99, in save
    obj = ProductProfile.objects.get(article=self.name__article)
AttributeError: 'ProductInShop' object has no attribute 'name__article'
C:\Users\11\Desktop\java\python_django\16_LoggingAndProfiling\app_shops\models.py changed, reloading.
Watching for file changes with StatReloader
C:\Users\11\Desktop\java\python_django\16_LoggingAndProfiling\app_shops\models.py changed, reloading.
Watching for file changes with StatReloader
Internal Server Error: /admin/app_shops/productinshop/add/
Traceback (most recent call last):
  File "C:\Python39\lib\site-packages\django\core\handlers\exception.py", line 47, in inner
    response = get_response(request)
  File "C:\Python39\lib\site-packages\django\core\handlers\base.py", line 181, in _get_response
    response = wrapped_callback(request, *callback_args, **callback_kwargs)
  File "C:\Python39\lib\site-packages\django\contrib\admin\options.py", line 622, in wrapper
    return self.admin_site.admin_view(view)(*args, **kwargs)
  File "C:\Python39\lib\site-packages\django\utils\decorators.py", line 130, in _wrapped_view
    response = view_func(request, *args, **kwargs)
  File "C:\Python39\lib\site-packages\django\views\decorators\cache.py", line 57, in _wrapped_view_func
    response = view_func(request, *args, **kwargs)
  File "C:\Python39\lib\site-packages\django\contrib\admin\sites.py", line 236, in inner
    return view(request, *args, **kwargs)
  File "C:\Python39\lib\site-packages\django\contrib\admin\options.py", line 1670, in add_view
    return self.changeform_view(request, None, form_url, extra_context)
  File "C:\Python39\lib\site-packages\django\utils\decorators.py", line 43, in _wrapper
    return bound_method(*args, **kwargs)
  File "C:\Python39\lib\site-packages\django\utils\decorators.py", line 130, in _wrapped_view
    response = view_func(request, *args, **kwargs)
  File "C:\Python39\lib\site-packages\django\contrib\admin\options.py", line 1549, in changeform_view
    return self._changeform_view(request, object_id, form_url, extra_context)
  File "C:\Python39\lib\site-packages\django\contrib\admin\options.py", line 1599, in _changeform_view
    self.save_model(request, new_object, form, not add)
  File "C:\Python39\lib\site-packages\django\contrib\admin\options.py", line 1108, in save_model
    obj.save()
  File "C:\Users\11\Desktop\java\python_django\16_LoggingAndProfiling\app_shops\models.py", line 99, in save
    obj = ProductProfile.objects.get(article=self.name__article)
AttributeError: 'ProductInShop' object has no attribute 'name__article'
C:\Users\11\Desktop\java\python_django\16_LoggingAndProfiling\app_shops\models.py changed, reloading.
Watching for file changes with StatReloader
C:\Users\11\Desktop\java\python_django\16_LoggingAndProfiling\app_shops\models.py changed, reloading.
Watching for file changes with StatReloader
Watching for file changes with StatReloader
C:\Users\11\Desktop\java\python_django\16_LoggingAndProfiling\app_shops\models.py changed, reloading.
Watching for file changes with StatReloader
C:\Users\11\Desktop\java\python_django\16_LoggingAndProfiling\app_shops\models.py changed, reloading.
Watching for file changes with StatReloader
Watching for file changes with StatReloader
Запрошена страница с корзиной пользователя
Запрошена страница с корзиной пользователя
C:\Users\11\Desktop\java\python_django\16_LoggingAndProfiling\app_shops\views.py changed, reloading.
Watching for file changes with StatReloader
Watching for file changes with StatReloader
Watching for file changes with StatReloader
Запрошена страница с корзиной пользователя
Not Found: /favicon.ico
C:\Users\11\Desktop\java\python_django\16_LoggingAndProfiling\app_shops\views.py changed, reloading.
Watching for file changes with StatReloader
Запрошена страница с корзиной пользователя
Запрошена страница с корзиной пользователя
Запрошена страница с корзиной пользователя
Запрошена страница с корзиной пользователя
Запрошена страница с корзиной пользователя
Запрошена страница с корзиной пользователя
Запрошена страница с корзиной пользователя
Watching for file changes with StatReloader
Запрошена страница с корзиной пользователя
Запрошена страница с корзиной пользователя
Internal Server Error: /shops/1/category/1/product/16
Traceback (most recent call last):
  File "C:\Users\11\Desktop\java\python_django\16_LoggingAndProfiling\app_shops\views.py", line 313, in product_detail
    in_garbage = UserGarbage.objects.get(product=product_in_shop, name=user_name, shop_id=shop_id)
  File "C:\Python39\lib\site-packages\django\db\models\manager.py", line 85, in manager_method
    return getattr(self.get_queryset(), name)(*args, **kwargs)
  File "C:\Python39\lib\site-packages\django\db\models\query.py", line 439, in get
    raise self.model.DoesNotExist(
app_shops.models.UserGarbage.DoesNotExist: UserGarbage matching query does not exist.

During handling of the above exception, another exception occurred:

Traceback (most recent call last):
  File "C:\Python39\lib\site-packages\django\core\handlers\exception.py", line 47, in inner
    response = get_response(request)
  File "C:\Python39\lib\site-packages\django\core\handlers\base.py", line 181, in _get_response
    response = wrapped_callback(request, *callback_args, **callback_kwargs)
  File "C:\Users\11\Desktop\java\python_django\16_LoggingAndProfiling\app_shops\views.py", line 318, in product_detail
    UserGarbage.objects.create(product=product_in_shop, name=user_name, amount=amount,
  File "C:\Python39\lib\site-packages\django\db\models\manager.py", line 85, in manager_method
    return getattr(self.get_queryset(), name)(*args, **kwargs)
  File "C:\Python39\lib\site-packages\django\db\models\query.py", line 457, in create
    obj.save(force_insert=True, using=self.db)
  File "C:\Users\11\Desktop\java\python_django\16_LoggingAndProfiling\app_shops\models.py", line 137, in save
    super(ProductInShop, self).save(*args, **kwargs)
TypeError: super(type, obj): obj must be an instance or subtype of type
Internal Server Error: /shops/1/category/1/product/16
Traceback (most recent call last):
  File "C:\Users\11\Desktop\java\python_django\16_LoggingAndProfiling\app_shops\views.py", line 313, in product_detail
    in_garbage = UserGarbage.objects.get(product=product_in_shop, name=user_name, shop_id=shop_id)
  File "C:\Python39\lib\site-packages\django\db\models\manager.py", line 85, in manager_method
    return getattr(self.get_queryset(), name)(*args, **kwargs)
  File "C:\Python39\lib\site-packages\django\db\models\query.py", line 439, in get
    raise self.model.DoesNotExist(
app_shops.models.UserGarbage.DoesNotExist: UserGarbage matching query does not exist.

During handling of the above exception, another exception occurred:

Traceback (most recent call last):
  File "C:\Python39\lib\site-packages\django\core\handlers\exception.py", line 47, in inner
    response = get_response(request)
  File "C:\Python39\lib\site-packages\django\core\handlers\base.py", line 181, in _get_response
    response = wrapped_callback(request, *callback_args, **callback_kwargs)
  File "C:\Users\11\Desktop\java\python_django\16_LoggingAndProfiling\app_shops\views.py", line 318, in product_detail
    UserGarbage.objects.create(product=product_in_shop, name=user_name, amount=amount,
  File "C:\Python39\lib\site-packages\django\db\models\manager.py", line 85, in manager_method
    return getattr(self.get_queryset(), name)(*args, **kwargs)
  File "C:\Python39\lib\site-packages\django\db\models\query.py", line 457, in create
    obj.save(force_insert=True, using=self.db)
  File "C:\Users\11\Desktop\java\python_django\16_LoggingAndProfiling\app_shops\models.py", line 137, in save
    super(ProductInShop, self).save(*args, **kwargs)
TypeError: super(type, obj): obj must be an instance or subtype of type
Watching for file changes with StatReloader
Watching for file changes with StatReloader
Watching for file changes with StatReloader
Запрошена страница с корзиной пользователя
C:\Users\11\Desktop\java\python_django\16_LoggingAndProfiling\app_shops\admin.py changed, reloading.
Watching for file changes with StatReloader
C:\Users\11\Desktop\java\python_django\16_LoggingAndProfiling\app_shops\admin.py changed, reloading.
Watching for file changes with StatReloader
Запрошена страница с корзиной пользователя
Internal Server Error: /shops/1/category/1/product/16
Traceback (most recent call last):
  File "C:\Users\11\Desktop\java\python_django\16_LoggingAndProfiling\app_shops\views.py", line 313, in product_detail
    in_garbage = UserGarbage.objects.get(product=product_in_shop, name=user_name, shop_id=shop_id)
  File "C:\Python39\lib\site-packages\django\db\models\manager.py", line 85, in manager_method
    return getattr(self.get_queryset(), name)(*args, **kwargs)
  File "C:\Python39\lib\site-packages\django\db\models\query.py", line 439, in get
    raise self.model.DoesNotExist(
app_shops.models.UserGarbage.DoesNotExist: UserGarbage matching query does not exist.

During handling of the above exception, another exception occurred:

Traceback (most recent call last):
  File "C:\Python39\lib\site-packages\django\db\backends\utils.py", line 85, in _execute
    return self.cursor.execute(sql, params)
  File "C:\Python39\lib\site-packages\django\db\backends\sqlite3\base.py", line 416, in execute
    return Database.Cursor.execute(self, query, params)
sqlite3.IntegrityError: NOT NULL constraint failed: app_shops_usergarbage.article

The above exception was the direct cause of the following exception:

Traceback (most recent call last):
  File "C:\Python39\lib\site-packages\django\core\handlers\exception.py", line 47, in inner
    response = get_response(request)
  File "C:\Python39\lib\site-packages\django\core\handlers\base.py", line 181, in _get_response
    response = wrapped_callback(request, *callback_args, **callback_kwargs)
  File "C:\Users\11\Desktop\java\python_django\16_LoggingAndProfiling\app_shops\views.py", line 318, in product_detail
    UserGarbage.objects.create(product=product_in_shop, name=user_name, amount=amount,
  File "C:\Python39\lib\site-packages\django\db\models\manager.py", line 85, in manager_method
    return getattr(self.get_queryset(), name)(*args, **kwargs)
  File "C:\Python39\lib\site-packages\django\db\models\query.py", line 457, in create
    obj.save(force_insert=True, using=self.db)
  File "C:\Python39\lib\site-packages\django\db\models\base.py", line 743, in save
    self.save_base(using=using, force_insert=force_insert,
  File "C:\Python39\lib\site-packages\django\db\models\base.py", line 780, in save_base
    updated = self._save_table(
  File "C:\Python39\lib\site-packages\django\db\models\base.py", line 885, in _save_table
    results = self._do_insert(cls._base_manager, using, fields, returning_fields, raw)
  File "C:\Python39\lib\site-packages\django\db\models\base.py", line 923, in _do_insert
    return manager._insert(
  File "C:\Python39\lib\site-packages\django\db\models\manager.py", line 85, in manager_method
    return getattr(self.get_queryset(), name)(*args, **kwargs)
  File "C:\Python39\lib\site-packages\django\db\models\query.py", line 1301, in _insert
    return query.get_compiler(using=using).execute_sql(returning_fields)
  File "C:\Python39\lib\site-packages\django\db\models\sql\compiler.py", line 1441, in execute_sql
    cursor.execute(sql, params)
  File "C:\Python39\lib\site-packages\debug_toolbar\panels\sql\tracking.py", line 205, in execute
    return self._record(self.cursor.execute, sql, params)
  File "C:\Python39\lib\site-packages\debug_toolbar\panels\sql\tracking.py", line 140, in _record
    return method(sql, params)
  File "C:\Python39\lib\site-packages\django\db\backends\utils.py", line 99, in execute
    return super().execute(sql, params)
  File "C:\Python39\lib\site-packages\django\db\backends\utils.py", line 67, in execute
    return self._execute_with_wrappers(sql, params, many=False, executor=self._execute)
  File "C:\Python39\lib\site-packages\django\db\backends\utils.py", line 76, in _execute_with_wrappers
    return executor(sql, params, many, context)
  File "C:\Python39\lib\site-packages\django\db\backends\utils.py", line 85, in _execute
    return self.cursor.execute(sql, params)
  File "C:\Python39\lib\site-packages\django\db\utils.py", line 90, in __exit__
    raise dj_exc_value.with_traceback(traceback) from exc_value
  File "C:\Python39\lib\site-packages\django\db\backends\utils.py", line 85, in _execute
    return self.cursor.execute(sql, params)
  File "C:\Python39\lib\site-packages\django\db\backends\sqlite3\base.py", line 416, in execute
    return Database.Cursor.execute(self, query, params)
django.db.utils.IntegrityError: NOT NULL constraint failed: app_shops_usergarbage.article
Watching for file changes with StatReloader
Запрошена страница с корзиной пользователя
Запрошена страница с корзиной пользователя
Запрошена страница с корзиной пользователя
Запрошена страница с корзиной пользователя
Запрошена страница с корзиной пользователя
Internal Server Error: /shops/1/category/1/product/3
Traceback (most recent call last):
  File "C:\Users\11\Desktop\java\python_django\16_LoggingAndProfiling\app_shops\views.py", line 313, in product_detail
    in_garbage = UserGarbage.objects.get(product=product_in_shop, name=user_name, shop_id=shop_id)
  File "C:\Python39\lib\site-packages\django\db\models\manager.py", line 85, in manager_method
    return getattr(self.get_queryset(), name)(*args, **kwargs)
  File "C:\Python39\lib\site-packages\django\db\models\query.py", line 439, in get
    raise self.model.DoesNotExist(
app_shops.models.UserGarbage.DoesNotExist: UserGarbage matching query does not exist.

During handling of the above exception, another exception occurred:

Traceback (most recent call last):
  File "C:\Python39\lib\site-packages\django\db\backends\utils.py", line 85, in _execute
    return self.cursor.execute(sql, params)
  File "C:\Python39\lib\site-packages\django\db\backends\sqlite3\base.py", line 416, in execute
    return Database.Cursor.execute(self, query, params)
sqlite3.IntegrityError: NOT NULL constraint failed: app_shops_usergarbage.article

The above exception was the direct cause of the following exception:

Traceback (most recent call last):
  File "C:\Python39\lib\site-packages\django\core\handlers\exception.py", line 47, in inner
    response = get_response(request)
  File "C:\Python39\lib\site-packages\django\core\handlers\base.py", line 181, in _get_response
    response = wrapped_callback(request, *callback_args, **callback_kwargs)
  File "C:\Users\11\Desktop\java\python_django\16_LoggingAndProfiling\app_shops\views.py", line 318, in product_detail
    UserGarbage.objects.create(product=product_in_shop, name=user_name, amount=amount,
  File "C:\Python39\lib\site-packages\django\db\models\manager.py", line 85, in manager_method
    return getattr(self.get_queryset(), name)(*args, **kwargs)
  File "C:\Python39\lib\site-packages\django\db\models\query.py", line 457, in create
    obj.save(force_insert=True, using=self.db)
  File "C:\Python39\lib\site-packages\django\db\models\base.py", line 743, in save
    self.save_base(using=using, force_insert=force_insert,
  File "C:\Python39\lib\site-packages\django\db\models\base.py", line 780, in save_base
    updated = self._save_table(
  File "C:\Python39\lib\site-packages\django\db\models\base.py", line 885, in _save_table
    results = self._do_insert(cls._base_manager, using, fields, returning_fields, raw)
  File "C:\Python39\lib\site-packages\django\db\models\base.py", line 923, in _do_insert
    return manager._insert(
  File "C:\Python39\lib\site-packages\django\db\models\manager.py", line 85, in manager_method
    return getattr(self.get_queryset(), name)(*args, **kwargs)
  File "C:\Python39\lib\site-packages\django\db\models\query.py", line 1301, in _insert
    return query.get_compiler(using=using).execute_sql(returning_fields)
  File "C:\Python39\lib\site-packages\django\db\models\sql\compiler.py", line 1441, in execute_sql
    cursor.execute(sql, params)
  File "C:\Python39\lib\site-packages\debug_toolbar\panels\sql\tracking.py", line 205, in execute
    return self._record(self.cursor.execute, sql, params)
  File "C:\Python39\lib\site-packages\debug_toolbar\panels\sql\tracking.py", line 140, in _record
    return method(sql, params)
  File "C:\Python39\lib\site-packages\django\db\backends\utils.py", line 99, in execute
    return super().execute(sql, params)
  File "C:\Python39\lib\site-packages\django\db\backends\utils.py", line 67, in execute
    return self._execute_with_wrappers(sql, params, many=False, executor=self._execute)
  File "C:\Python39\lib\site-packages\django\db\backends\utils.py", line 76, in _execute_with_wrappers
    return executor(sql, params, many, context)
  File "C:\Python39\lib\site-packages\django\db\backends\utils.py", line 85, in _execute
    return self.cursor.execute(sql, params)
  File "C:\Python39\lib\site-packages\django\db\utils.py", line 90, in __exit__
    raise dj_exc_value.with_traceback(traceback) from exc_value
  File "C:\Python39\lib\site-packages\django\db\backends\utils.py", line 85, in _execute
    return self.cursor.execute(sql, params)
  File "C:\Python39\lib\site-packages\django\db\backends\sqlite3\base.py", line 416, in execute
    return Database.Cursor.execute(self, query, params)
django.db.utils.IntegrityError: NOT NULL constraint failed: app_shops_usergarbage.article
Watching for file changes with StatReloader
Запрошена страница с корзиной пользователя
Internal Server Error: /shops/1/category/1/product/16
Traceback (most recent call last):
  File "C:\Users\11\Desktop\java\python_django\16_LoggingAndProfiling\app_shops\views.py", line 313, in product_detail
    in_garbage = UserGarbage.objects.get(product=product_in_shop, name=user_name, shop_id=shop_id)
  File "C:\Python39\lib\site-packages\django\db\models\manager.py", line 85, in manager_method
    return getattr(self.get_queryset(), name)(*args, **kwargs)
  File "C:\Python39\lib\site-packages\django\db\models\query.py", line 439, in get
    raise self.model.DoesNotExist(
app_shops.models.UserGarbage.DoesNotExist: UserGarbage matching query does not exist.

During handling of the above exception, another exception occurred:

Traceback (most recent call last):
  File "C:\Python39\lib\site-packages\django\db\backends\utils.py", line 85, in _execute
    return self.cursor.execute(sql, params)
  File "C:\Python39\lib\site-packages\django\db\backends\sqlite3\base.py", line 416, in execute
    return Database.Cursor.execute(self, query, params)
sqlite3.IntegrityError: NOT NULL constraint failed: app_shops_usergarbage.article

The above exception was the direct cause of the following exception:

Traceback (most recent call last):
  File "C:\Python39\lib\site-packages\django\core\handlers\exception.py", line 47, in inner
    response = get_response(request)
  File "C:\Python39\lib\site-packages\django\core\handlers\base.py", line 181, in _get_response
    response = wrapped_callback(request, *callback_args, **callback_kwargs)
  File "C:\Users\11\Desktop\java\python_django\16_LoggingAndProfiling\app_shops\views.py", line 318, in product_detail
    UserGarbage.objects.create(product=product_in_shop, name=user_name, amount=amount,
  File "C:\Python39\lib\site-packages\django\db\models\manager.py", line 85, in manager_method
    return getattr(self.get_queryset(), name)(*args, **kwargs)
  File "C:\Python39\lib\site-packages\django\db\models\query.py", line 457, in create
    obj.save(force_insert=True, using=self.db)
  File "C:\Python39\lib\site-packages\django\db\models\base.py", line 743, in save
    self.save_base(using=using, force_insert=force_insert,
  File "C:\Python39\lib\site-packages\django\db\models\base.py", line 780, in save_base
    updated = self._save_table(
  File "C:\Python39\lib\site-packages\django\db\models\base.py", line 885, in _save_table
    results = self._do_insert(cls._base_manager, using, fields, returning_fields, raw)
  File "C:\Python39\lib\site-packages\django\db\models\base.py", line 923, in _do_insert
    return manager._insert(
  File "C:\Python39\lib\site-packages\django\db\models\manager.py", line 85, in manager_method
    return getattr(self.get_queryset(), name)(*args, **kwargs)
  File "C:\Python39\lib\site-packages\django\db\models\query.py", line 1301, in _insert
    return query.get_compiler(using=using).execute_sql(returning_fields)
  File "C:\Python39\lib\site-packages\django\db\models\sql\compiler.py", line 1441, in execute_sql
    cursor.execute(sql, params)
  File "C:\Python39\lib\site-packages\debug_toolbar\panels\sql\tracking.py", line 205, in execute
    return self._record(self.cursor.execute, sql, params)
  File "C:\Python39\lib\site-packages\debug_toolbar\panels\sql\tracking.py", line 140, in _record
    return method(sql, params)
  File "C:\Python39\lib\site-packages\django\db\backends\utils.py", line 99, in execute
    return super().execute(sql, params)
  File "C:\Python39\lib\site-packages\django\db\backends\utils.py", line 67, in execute
    return self._execute_with_wrappers(sql, params, many=False, executor=self._execute)
  File "C:\Python39\lib\site-packages\django\db\backends\utils.py", line 76, in _execute_with_wrappers
    return executor(sql, params, many, context)
  File "C:\Python39\lib\site-packages\django\db\backends\utils.py", line 85, in _execute
    return self.cursor.execute(sql, params)
  File "C:\Python39\lib\site-packages\django\db\utils.py", line 90, in __exit__
    raise dj_exc_value.with_traceback(traceback) from exc_value
  File "C:\Python39\lib\site-packages\django\db\backends\utils.py", line 85, in _execute
    return self.cursor.execute(sql, params)
  File "C:\Python39\lib\site-packages\django\db\backends\sqlite3\base.py", line 416, in execute
    return Database.Cursor.execute(self, query, params)
django.db.utils.IntegrityError: NOT NULL constraint failed: app_shops_usergarbage.article
Запрошена страница с корзиной пользователя
Запрошена страница с корзиной пользователя
Запрошена страница с корзиной пользователя
Запрошена страница с корзиной пользователя
Internal Server Error: /shops/1/category/1/product/4
Traceback (most recent call last):
  File "C:\Users\11\Desktop\java\python_django\16_LoggingAndProfiling\app_shops\views.py", line 313, in product_detail
    in_garbage = UserGarbage.objects.get(product=product_in_shop, name=user_name, shop_id=shop_id)
  File "C:\Python39\lib\site-packages\django\db\models\manager.py", line 85, in manager_method
    return getattr(self.get_queryset(), name)(*args, **kwargs)
  File "C:\Python39\lib\site-packages\django\db\models\query.py", line 439, in get
    raise self.model.DoesNotExist(
app_shops.models.UserGarbage.DoesNotExist: UserGarbage matching query does not exist.

During handling of the above exception, another exception occurred:

Traceback (most recent call last):
  File "C:\Python39\lib\site-packages\django\db\backends\utils.py", line 85, in _execute
    return self.cursor.execute(sql, params)
  File "C:\Python39\lib\site-packages\django\db\backends\sqlite3\base.py", line 416, in execute
    return Database.Cursor.execute(self, query, params)
sqlite3.IntegrityError: NOT NULL constraint failed: app_shops_usergarbage.article

The above exception was the direct cause of the following exception:

Traceback (most recent call last):
  File "C:\Python39\lib\site-packages\django\core\handlers\exception.py", line 47, in inner
    response = get_response(request)
  File "C:\Python39\lib\site-packages\django\core\handlers\base.py", line 181, in _get_response
    response = wrapped_callback(request, *callback_args, **callback_kwargs)
  File "C:\Users\11\Desktop\java\python_django\16_LoggingAndProfiling\app_shops\views.py", line 318, in product_detail
    UserGarbage.objects.create(product=product_in_shop, name=user_name, amount=amount,
  File "C:\Python39\lib\site-packages\django\db\models\manager.py", line 85, in manager_method
    return getattr(self.get_queryset(), name)(*args, **kwargs)
  File "C:\Python39\lib\site-packages\django\db\models\query.py", line 457, in create
    obj.save(force_insert=True, using=self.db)
  File "C:\Python39\lib\site-packages\django\db\models\base.py", line 743, in save
    self.save_base(using=using, force_insert=force_insert,
  File "C:\Python39\lib\site-packages\django\db\models\base.py", line 780, in save_base
    updated = self._save_table(
  File "C:\Python39\lib\site-packages\django\db\models\base.py", line 885, in _save_table
    results = self._do_insert(cls._base_manager, using, fields, returning_fields, raw)
  File "C:\Python39\lib\site-packages\django\db\models\base.py", line 923, in _do_insert
    return manager._insert(
  File "C:\Python39\lib\site-packages\django\db\models\manager.py", line 85, in manager_method
    return getattr(self.get_queryset(), name)(*args, **kwargs)
  File "C:\Python39\lib\site-packages\django\db\models\query.py", line 1301, in _insert
    return query.get_compiler(using=using).execute_sql(returning_fields)
  File "C:\Python39\lib\site-packages\django\db\models\sql\compiler.py", line 1441, in execute_sql
    cursor.execute(sql, params)
  File "C:\Python39\lib\site-packages\debug_toolbar\panels\sql\tracking.py", line 205, in execute
    return self._record(self.cursor.execute, sql, params)
  File "C:\Python39\lib\site-packages\debug_toolbar\panels\sql\tracking.py", line 140, in _record
    return method(sql, params)
  File "C:\Python39\lib\site-packages\django\db\backends\utils.py", line 99, in execute
    return super().execute(sql, params)
  File "C:\Python39\lib\site-packages\django\db\backends\utils.py", line 67, in execute
    return self._execute_with_wrappers(sql, params, many=False, executor=self._execute)
  File "C:\Python39\lib\site-packages\django\db\backends\utils.py", line 76, in _execute_with_wrappers
    return executor(sql, params, many, context)
  File "C:\Python39\lib\site-packages\django\db\backends\utils.py", line 85, in _execute
    return self.cursor.execute(sql, params)
  File "C:\Python39\lib\site-packages\django\db\utils.py", line 90, in __exit__
    raise dj_exc_value.with_traceback(traceback) from exc_value
  File "C:\Python39\lib\site-packages\django\db\backends\utils.py", line 85, in _execute
    return self.cursor.execute(sql, params)
  File "C:\Python39\lib\site-packages\django\db\backends\sqlite3\base.py", line 416, in execute
    return Database.Cursor.execute(self, query, params)
django.db.utils.IntegrityError: NOT NULL constraint failed: app_shops_usergarbage.article
Watching for file changes with StatReloader
Запрошена страница с корзиной пользователя
Запрошена страница с корзиной пользователя
C:\Users\11\Desktop\java\python_django\16_LoggingAndProfiling\app_shops\admin.py changed, reloading.
Watching for file changes with StatReloader
C:\Users\11\Desktop\java\python_django\16_LoggingAndProfiling\app_shops\admin.py changed, reloading.
Watching for file changes with StatReloader
C:\Users\11\Desktop\java\python_django\16_LoggingAndProfiling\app_shops\admin.py changed, reloading.
Watching for file changes with StatReloader
Watching for file changes with StatReloader
Запрошена страница с корзиной пользователя
Internal Server Error: /shops/1/category/1/product/3
Traceback (most recent call last):
  File "C:\Python39\lib\site-packages\django\core\handlers\exception.py", line 47, in inner
    response = get_response(request)
  File "C:\Python39\lib\site-packages\django\core\handlers\base.py", line 188, in _get_response
    self.check_response(response, callback)
  File "C:\Python39\lib\site-packages\django\core\handlers\base.py", line 309, in check_response
    raise ValueError(
ValueError: The view app_shops.views.product_detail didn't return an HttpResponse object. It returned None instead.
C:\Users\11\Desktop\java\python_django\16_LoggingAndProfiling\app_shops\views.py changed, reloading.
Watching for file changes with StatReloader
Watching for file changes with StatReloader
Запрошена страница с корзиной пользователя
Internal Server Error: /shops/1/category/1/product/16
Traceback (most recent call last):
  File "C:\Python39\lib\site-packages\django\core\handlers\exception.py", line 47, in inner
    response = get_response(request)
  File "C:\Python39\lib\site-packages\django\core\handlers\base.py", line 181, in _get_response
    response = wrapped_callback(request, *callback_args, **callback_kwargs)
  File "C:\Users\11\Desktop\java\python_django\16_LoggingAndProfiling\app_shops\views.py", line 302, in product_detail
    in_shop = ProductInShop.objects.get(article=article)
  File "C:\Python39\lib\site-packages\django\db\models\manager.py", line 85, in manager_method
    return getattr(self.get_queryset(), name)(*args, **kwargs)
  File "C:\Python39\lib\site-packages\django\db\models\query.py", line 439, in get
    raise self.model.DoesNotExist(
app_shops.models.ProductInShop.DoesNotExist: ProductInShop matching query does not exist.
C:\Users\11\Desktop\java\python_django\16_LoggingAndProfiling\app_shops\views.py changed, reloading.
Watching for file changes with StatReloader
Запрошена страница с корзиной пользователя
Запрошена страница с корзиной пользователя
Запрошена страница с корзиной пользователя
Запрошена страница с корзиной пользователя
Запрошена страница с корзиной пользователя
Запрошена страница с корзиной пользователя
Запрошена страница с корзиной пользователя
C:\Users\11\Desktop\java\python_django\16_LoggingAndProfiling\app_shops\views.py changed, reloading.
Watching for file changes with StatReloader
Запрошена страница с корзиной пользователя
Запрошена страница с корзиной пользователя
Запрошена страница с корзиной пользователя
Запрошена страница с корзиной пользователя
Запрошена страница с корзиной пользователя
C:\Users\11\Desktop\java\python_django\16_LoggingAndProfiling\app_shops\views.py changed, reloading.
Watching for file changes with StatReloader
C:\Users\11\Desktop\java\python_django\16_LoggingAndProfiling\app_shops\views.py changed, reloading.
Watching for file changes with StatReloader
C:\Users\11\Desktop\java\python_django\16_LoggingAndProfiling\app_shops\views.py changed, reloading.
Watching for file changes with StatReloader
Запрошена страница с корзиной пользователя
Запрошена страница с корзиной пользователя
Запрошена страница с корзиной пользователя
Запрошена страница с корзиной пользователя
C:\Users\11\Desktop\java\python_django\16_LoggingAndProfiling\app_shops\urls.py changed, reloading.
Watching for file changes with StatReloader
C:\Users\11\Desktop\java\python_django\16_LoggingAndProfiling\app_shops\urls.py changed, reloading.
Watching for file changes with StatReloader
Not Found: /shops/36/category/15/product/105
Not Found: /shops/36/category/15/product/105
C:\Users\11\Desktop\java\python_django\16_LoggingAndProfiling\app_shops\urls.py changed, reloading.
Watching for file changes with StatReloader
Not Found: /shops/36/category/15/product/105
Запрошена страница с корзиной пользователя
Not Found: /shops/36/category/15/product/258/1189,36
C:\Users\11\Desktop\java\python_django\16_LoggingAndProfiling\app_shops\urls.py changed, reloading.
Watching for file changes with StatReloader
Not Found: /shops/36/category/15/product/314/1245,36
C:\Users\11\Desktop\java\python_django\16_LoggingAndProfiling\app_shops\urls.py changed, reloading.
Watching for file changes with StatReloader
Not Found: /shops/36/category/15/product/105/1036,36
Not Found: /shops/36/category/15/product/319/1250,36
C:\Users\11\Desktop\java\python_django\16_LoggingAndProfiling\app_shops\urls.py changed, reloading.
Watching for file changes with StatReloader
Not Found: /shops/36/category/15/product/105/1036,36
C:\Users\11\Desktop\java\python_django\16_LoggingAndProfiling\app_shops\urls.py changed, reloading.
Watching for file changes with StatReloader
C:\Users\11\Desktop\java\python_django\16_LoggingAndProfiling\app_shops\urls.py changed, reloading.
Watching for file changes with StatReloader
Not Found: /shops/36/category/15/product/105/1036,36
C:\Users\11\Desktop\java\python_django\16_LoggingAndProfiling\app_shops\urls.py changed, reloading.
Watching for file changes with StatReloader
Not Found: /shops/36/category/15/product/105/1036,36
Not Found: /shops/36/category/15/product/187/1118,36
C:\Users\11\Desktop\java\python_django\16_LoggingAndProfiling\app_shops\urls.py changed, reloading.
Watching for file changes with StatReloader
Not Found: /shops/36/category/15/product/187/1118,36
C:\Users\11\Desktop\java\python_django\16_LoggingAndProfiling\app_shops\urls.py changed, reloading.
Watching for file changes with StatReloader
Not Found: /shops/36/category/15/product/187/1118
Not Found: /shops/36/category/15/product/187/1212
C:\Users\11\Desktop\java\python_django\16_LoggingAndProfiling\app_shops\urls.py changed, reloading.
Watching for file changes with StatReloader
Not Found: /shops/36/category/15/product/187/1212
Not Found: /shops/36/category/15/product/187/1212/
C:\Users\11\Desktop\java\python_django\16_LoggingAndProfiling\app_shops\urls.py changed, reloading.
Watching for file changes with StatReloader
Watching for file changes with StatReloader
Not Found: /shops/36/category/15/product/187/1212/
Запрошена страница с корзиной пользователя
Not Found: /shops/36/category/15/product/187/1212,12
C:\Users\11\Desktop\java\python_django\16_LoggingAndProfiling\app_shops\urls.py changed, reloading.
Watching for file changes with StatReloader
Watching for file changes with StatReloader
Запрошена страница с корзиной пользователя
Запрошена страница с корзиной пользователя
Запрошена страница с корзиной пользователя
Запрошена страница с корзиной пользователя
Запрошена страница с корзиной пользователя
C:\Users\11\Desktop\java\python_django\16_LoggingAndProfiling\app_shops\views.py changed, reloading.
Watching for file changes with StatReloader
Запрошена страница с корзиной пользователя
Internal Server Error: /shops/34/category/9
Traceback (most recent call last):
  File "C:\Python39\lib\site-packages\django\core\handlers\exception.py", line 47, in inner
    response = get_response(request)
  File "C:\Python39\lib\site-packages\django\core\handlers\base.py", line 181, in _get_response
    response = wrapped_callback(request, *callback_args, **callback_kwargs)
  File "C:\Users\11\Desktop\java\python_django\16_LoggingAndProfiling\app_shops\views.py", line 149, in product_list
    print(request.pk1)
AttributeError: 'WSGIRequest' object has no attribute 'pk1'
C:\Users\11\Desktop\java\python_django\16_LoggingAndProfiling\app_shops\views.py changed, reloading.
Watching for file changes with StatReloader
Запрошена страница с корзиной пользователя
C:\Users\11\Desktop\java\python_django\16_LoggingAndProfiling\app_shops\views.py changed, reloading.
Watching for file changes with StatReloader
Запрошена страница с корзиной пользователя
C:\Users\11\Desktop\java\python_django\16_LoggingAndProfiling\app_shops\views.py changed, reloading.
Watching for file changes with StatReloader
Запрошена страница с корзиной пользователя
Запрошена страница с корзиной пользователя
Запрошена страница с корзиной пользователя
Запрошена страница с корзиной пользователя
C:\Users\11\Desktop\java\python_django\16_LoggingAndProfiling\app_shops\views.py changed, reloading.
Watching for file changes with StatReloader
Запрошена страница с корзиной пользователя
C:\Users\11\Desktop\java\python_django\16_LoggingAndProfiling\app_shops\views.py changed, reloading.
Watching for file changes with StatReloader
Запрошена страница с корзиной пользователя
Запрошена страница с корзиной пользователя
Запрошена страница с корзиной пользователя
Запрошена страница с корзиной пользователя
C:\Users\11\Desktop\java\python_django\16_LoggingAndProfiling\app_shops\views.py changed, reloading.
Watching for file changes with StatReloader
Запрошена страница с корзиной пользователя
Запрошена страница с корзиной пользователя
Запрошена страница с корзиной пользователя
Запрошена страница с корзиной пользователя
Запрошена страница с корзиной пользователя
Запрошена страница с корзиной пользователя
Запрошена страница с корзиной пользователя
Запрошена страница с корзиной пользователя
Запрошена страница с корзиной пользователя
Запрошена страница с корзиной пользователя
Запрошена страница с корзиной пользователя
C:\Users\11\Desktop\java\python_django\16_LoggingAndProfiling\app_shops\views.py changed, reloading.
Watching for file changes with StatReloader
Запрошена страница с корзиной пользователя
Запрошена страница с корзиной пользователя
Запрошена страница с корзиной пользователя
Запрошена страница с корзиной пользователя
Запрошена страница с корзиной пользователя
Watching for file changes with StatReloader
Запрошена страница с корзиной пользователя
Запрошена страница с корзиной пользователя
Запрошена страница с корзиной пользователя
Запрошена страница с корзиной пользователя
Запрошена страница с корзиной пользователя
Запрошена страница с корзиной пользователя
Запрошена страница с корзиной пользователя
Запрошена страница с корзиной пользователя
Internal Server Error: /shops/check
Traceback (most recent call last):
  File "C:\Python39\lib\site-packages\django\core\handlers\exception.py", line 47, in inner
    response = get_response(request)
  File "C:\Python39\lib\site-packages\django\core\handlers\base.py", line 181, in _get_response
    response = wrapped_callback(request, *callback_args, **callback_kwargs)
  File "C:\Users\11\Desktop\java\python_django\16_LoggingAndProfiling\app_shops\views.py", line 79, in check_payment
    f' {round(extra_context["user_profile"].purchases_count, 2)}'  # Profile.objects.get(user=request.user)
TypeError: type CombinedExpression doesn't define __round__ method
C:\Users\11\Desktop\java\python_django\16_LoggingAndProfiling\app_shops\views.py changed, reloading.
Watching for file changes with StatReloader
Запрошена страница с корзиной пользователя
Запрошена страница с корзиной пользователя
Запрошена страница с корзиной пользователя
C:\Users\11\Desktop\java\python_django\16_LoggingAndProfiling\app_shops\views.py changed, reloading.
Watching for file changes with StatReloader
Запрошена страница с корзиной пользователя
Запрошена страница с корзиной пользователя
Запрошена страница с корзиной пользователя
Запрошена страница с корзиной пользователя
Запрошена страница с корзиной пользователя
Запрошена страница с корзиной пользователя
Запрошена страница с корзиной пользователя
Запрошена страница с корзиной пользователя
Запрошена страница с корзиной пользователя
Запрошена страница с корзиной пользователя
Запрошена страница с корзиной пользователя
Запрошена страница с корзиной пользователя
Запрошена страница с корзиной пользователя
Запрошена страница с корзиной пользователя
Запрошена страница с корзиной пользователя
Запрошена страница с корзиной пользователя
Запрошена страница с корзиной пользователя
Internal Server Error: /shops/check
Traceback (most recent call last):
  File "C:\Python39\lib\site-packages\django\core\handlers\exception.py", line 47, in inner
    response = get_response(request)
  File "C:\Python39\lib\site-packages\django\core\handlers\base.py", line 181, in _get_response
    response = wrapped_callback(request, *callback_args, **callback_kwargs)
  File "C:\Users\11\Desktop\java\python_django\16_LoggingAndProfiling\app_shops\views.py", line 79, in check_payment
    f' {round(extra_context["user_profile"].purchases_count, 2)}'  # Profile.objects.get(user=request.user)
TypeError: type CombinedExpression doesn't define __round__ method
Запрошена страница с корзиной пользователя
Запрошена страница с корзиной пользователя
C:\Users\11\Desktop\java\python_django\16_LoggingAndProfiling\app_shops\views.py changed, reloading.
Watching for file changes with StatReloader
C:\Users\11\Desktop\java\python_django\16_LoggingAndProfiling\app_shops\views.py changed, reloading.
Watching for file changes with StatReloader
Запрошена страница с корзиной пользователя
Запрошена страница с корзиной пользователя
Запрошена страница с корзиной пользователя
Запрошена страница с корзиной пользователя
Запрошена страница с корзиной пользователя
Запрошена страница с корзиной пользователя
Запрошена страница с корзиной пользователя
Запрошена страница с корзиной пользователя
Запрошена страница с корзиной пользователя
Запрошена страница с корзиной пользователя
Запрошена страница с корзиной пользователя
Запрошена страница с корзиной пользователя
Запрошена страница с корзиной пользователя
Запрошена страница с корзиной пользователя
Запрошена страница с корзиной пользователя
Запрошена страница с корзиной пользователя
Запрошена страница с корзиной пользователя
Запрошена страница с корзиной пользователя
Запрошена страница с корзиной пользователя
Запрошена страница с корзиной пользователя
Watching for file changes with StatReloader
Запрошена страница с корзиной пользователя
Not Found: /favicon.ico
Запрошена страница с корзиной пользователя
Запрошена страница с корзиной пользователя
Запрошена страница с корзиной пользователя
Запрошена страница с корзиной пользователя
Запрошена страница с корзиной пользователя
C:\Users\11\Desktop\java\python_django\16_LoggingAndProfiling\app_shops\views.py changed, reloading.
Watching for file changes with StatReloader
Запрошена страница с корзиной пользователя
Запрошена страница с корзиной пользователя
Запрошена страница с корзиной пользователя
Запрошена страница с корзиной пользователя
Запрошена страница с корзиной пользователя
Запрошена страница с корзиной пользователя
Запрошена страница с корзиной пользователя
Запрошена страница с корзиной пользователя
Internal Server Error: /shops/check
Traceback (most recent call last):
  File "C:\Python39\lib\site-packages\django\core\handlers\exception.py", line 47, in inner
    response = get_response(request)
  File "C:\Python39\lib\site-packages\django\core\handlers\base.py", line 181, in _get_response
    response = wrapped_callback(request, *callback_args, **callback_kwargs)
  File "C:\Users\11\Desktop\java\python_django\16_LoggingAndProfiling\app_shops\views.py", line 75, in check_payment
    purchases_count = round(extra_context["user_profile"].purchases_count, 2)
TypeError: type CombinedExpression doesn't define __round__ method
Watching for file changes with StatReloader
Запрошена страница с корзиной пользователя
Запрошена страница с корзиной пользователя
C:\Users\11\Desktop\java\python_django\16_LoggingAndProfiling\app_shops\views.py changed, reloading.
Watching for file changes with StatReloader
Запрошена страница с корзиной пользователя
Watching for file changes with StatReloader
Запрошена страница с корзиной пользователя
Запрошена страница с корзиной пользователя
Запрошена страница с корзиной пользователя
Запрошена страница с корзиной пользователя
Запрошена страница с корзиной пользователя
Запрошена страница с корзиной пользователя
C:\Users\11\Desktop\java\python_django\16_LoggingAndProfiling\app_shops\views.py changed, reloading.
Watching for file changes with StatReloader
Запрошена страница с корзиной пользователя
Запрошена страница с корзиной пользователя
Internal Server Error: /shops/
Traceback (most recent call last):
  File "C:\Python39\lib\site-packages\django\core\handlers\exception.py", line 47, in inner
    response = get_response(request)
  File "C:\Python39\lib\site-packages\django\core\handlers\base.py", line 181, in _get_response
    response = wrapped_callback(request, *callback_args, **callback_kwargs)
  File "C:\Users\11\Desktop\java\python_django\16_LoggingAndProfiling\app_shops\views.py", line 21, in start_shops
    content = start_page_context_cache(request)
  File "C:\Users\11\Desktop\java\python_django\16_LoggingAndProfiling\market\views.py", line 87, in start_page_context_cache
    print(data[request.user])
KeyError: <SimpleLazyObject: <User: pavlove>>
C:\Users\11\Desktop\java\python_django\16_LoggingAndProfiling\market\views.py changed, reloading.
Watching for file changes with StatReloader
Запрошена страница с корзиной пользователя
Internal Server Error: /shops/
Traceback (most recent call last):
  File "C:\Python39\lib\site-packages\django\core\handlers\exception.py", line 47, in inner
    response = get_response(request)
  File "C:\Python39\lib\site-packages\django\core\handlers\base.py", line 181, in _get_response
    response = wrapped_callback(request, *callback_args, **callback_kwargs)
  File "C:\Users\11\Desktop\java\python_django\16_LoggingAndProfiling\app_shops\views.py", line 21, in start_shops
    content = start_page_context_cache(request)
  File "C:\Users\11\Desktop\java\python_django\16_LoggingAndProfiling\market\views.py", line 87, in start_page_context_cache
    print(data[request.user.username])
KeyError: 'pavlove'
C:\Users\11\Desktop\java\python_django\16_LoggingAndProfiling\market\views.py changed, reloading.
Watching for file changes with StatReloader
Запрошена страница с корзиной пользователя
C:\Users\11\Desktop\java\python_django\16_LoggingAndProfiling\market\views.py changed, reloading.
Watching for file changes with StatReloader
Запрошена страница с корзиной пользователя
C:\Users\11\Desktop\java\python_django\16_LoggingAndProfiling\app_shops\views.py changed, reloading.
Watching for file changes with StatReloader
Запрошена страница с корзиной пользователя
C:\Users\11\Desktop\java\python_django\16_LoggingAndProfiling\app_shops\views.py changed, reloading.
Watching for file changes with StatReloader
Запрошена страница с корзиной пользователя
C:\Users\11\Desktop\java\python_django\16_LoggingAndProfiling\app_shops\views.py changed, reloading.
Watching for file changes with StatReloader
Запрошена страница с корзиной пользователя
C:\Users\11\Desktop\java\python_django\16_LoggingAndProfiling\app_shops\views.py changed, reloading.
Watching for file changes with StatReloader
Запрошена страница с корзиной пользователя
C:\Users\11\Desktop\java\python_django\16_LoggingAndProfiling\app_shops\views.py changed, reloading.
Watching for file changes with StatReloader
Запрошена страница с корзиной пользователя
Not Found: /rating
Not Found: /statistic/rating
Запрошена страница с корзиной пользователя
C:\Users\11\Desktop\java\python_django\16_LoggingAndProfiling\app_shops\urls.py changed, reloading.
Watching for file changes with StatReloader
Watching for file changes with StatReloader
Not Found: /shops/product_list
Запрошена страница с корзиной пользователя
C:\Users\11\Desktop\java\python_django\16_LoggingAndProfiling\add_statistics\views.py changed, reloading.
Watching for file changes with StatReloader
Запрошена страница с корзиной пользователя
C:\Users\11\Desktop\java\python_django\16_LoggingAndProfiling\add_statistics\views.py changed, reloading.
Watching for file changes with StatReloader
C:\Users\11\Desktop\java\python_django\16_LoggingAndProfiling\add_statistics\views.py changed, reloading.
Watching for file changes with StatReloader
C:\Users\11\Desktop\java\python_django\16_LoggingAndProfiling\add_statistics\views.py changed, reloading.
Watching for file changes with StatReloader
C:\Users\11\Desktop\java\python_django\16_LoggingAndProfiling\add_statistics\views.py changed, reloading.
Watching for file changes with StatReloader
Запрошена страница с корзиной пользователя
C:\Users\11\Desktop\java\python_django\16_LoggingAndProfiling\add_statistics\views.py changed, reloading.
Watching for file changes with StatReloader
C:\Users\11\Desktop\java\python_django\16_LoggingAndProfiling\add_statistics\views.py changed, reloading.
Watching for file changes with StatReloader
Запрошена страница с корзиной пользователя
C:\Users\11\Desktop\java\python_django\16_LoggingAndProfiling\add_statistics\views.py changed, reloading.
Watching for file changes with StatReloader
Internal Server Error: /statistics/rating/
Traceback (most recent call last):
  File "C:\Python39\lib\site-packages\django\core\handlers\exception.py", line 47, in inner
    response = get_response(request)
  File "C:\Python39\lib\site-packages\django\core\handlers\base.py", line 181, in _get_response
    response = wrapped_callback(request, *callback_args, **callback_kwargs)
  File "C:\Users\11\Desktop\java\python_django\16_LoggingAndProfiling\add_statistics\views.py", line 148, in products_rating_list
    context = context_return(queryset)
TypeError: context_return() missing 1 required positional argument: 'queryset'
C:\Users\11\Desktop\java\python_django\16_LoggingAndProfiling\add_statistics\views.py changed, reloading.
Watching for file changes with StatReloader
Запрошена страница с корзиной пользователя
C:\Users\11\Desktop\java\python_django\16_LoggingAndProfiling\add_statistics\urls.py changed, reloading.
Watching for file changes with StatReloader
C:\Users\11\Desktop\java\python_django\16_LoggingAndProfiling\add_statistics\views.py changed, reloading.
Watching for file changes with StatReloader
C:\Users\11\Desktop\java\python_django\16_LoggingAndProfiling\add_statistics\urls.py changed, reloading.
Watching for file changes with StatReloader
Internal Server Error: /statistics/rating/
Traceback (most recent call last):
  File "C:\Python39\lib\site-packages\django\core\handlers\exception.py", line 47, in inner
    response = get_response(request)
  File "C:\Python39\lib\site-packages\django\core\handlers\base.py", line 181, in _get_response
    response = wrapped_callback(request, *callback_args, **callback_kwargs)
TypeError: as_view() takes 1 positional argument but 2 were given
Запрошена страница с корзиной пользователя
Internal Server Error: /statistics/full_rating/
Traceback (most recent call last):
  File "C:\Python39\lib\site-packages\django\core\handlers\exception.py", line 47, in inner
    response = get_response(request)
  File "C:\Python39\lib\site-packages\django\core\handlers\base.py", line 181, in _get_response
    response = wrapped_callback(request, *callback_args, **callback_kwargs)
TypeError: as_view() takes 1 positional argument but 2 were given
C:\Users\11\Desktop\java\python_django\16_LoggingAndProfiling\add_statistics\views.py changed, reloading.
Watching for file changes with StatReloader
C:\Users\11\Desktop\java\python_django\16_LoggingAndProfiling\add_statistics\views.py changed, reloading.
Watching for file changes with StatReloader
Запрошена страница с корзиной пользователя
Internal Server Error: /statistics/full_rating/
Traceback (most recent call last):
  File "C:\Python39\lib\site-packages\django\core\handlers\exception.py", line 47, in inner
    response = get_response(request)
  File "C:\Python39\lib\site-packages\django\core\handlers\base.py", line 181, in _get_response
    response = wrapped_callback(request, *callback_args, **callback_kwargs)
TypeError: as_view() takes 1 positional argument but 2 were given
C:\Users\11\Desktop\java\python_django\16_LoggingAndProfiling\add_statistics\urls.py changed, reloading.
Watching for file changes with StatReloader
C:\Users\11\Desktop\java\python_django\16_LoggingAndProfiling\add_statistics\views.py changed, reloading.
Watching for file changes with StatReloader
C:\Users\11\Desktop\java\python_django\16_LoggingAndProfiling\add_statistics\views.py changed, reloading.
Watching for file changes with StatReloader
Not Found: /favicon.ico
C:\Users\11\Desktop\java\python_django\16_LoggingAndProfiling\add_statistics\views.py changed, reloading.
Watching for file changes with StatReloader
Запрошена страница с корзиной пользователя
C:\Users\11\Desktop\java\python_django\16_LoggingAndProfiling\add_statistics\views.py changed, reloading.
Watching for file changes with StatReloader
Запрошена страница с корзиной пользователя
Not Found: /favicon.ico
C:\Users\11\Desktop\java\python_django\16_LoggingAndProfiling\add_statistics\views.py changed, reloading.
Watching for file changes with StatReloader
Запрошена страница с корзиной пользователя
C:\Users\11\Desktop\java\python_django\16_LoggingAndProfiling\add_statistics\views.py changed, reloading.
Watching for file changes with StatReloader
Запрошена страница с корзиной пользователя
C:\Users\11\Desktop\java\python_django\16_LoggingAndProfiling\add_statistics\views.py changed, reloading.
Watching for file changes with StatReloader
Запрошена страница с корзиной пользователя
C:\Users\11\Desktop\java\python_django\16_LoggingAndProfiling\add_statistics\views.py changed, reloading.
Watching for file changes with StatReloader
Запрошена страница с корзиной пользователя
C:\Users\11\Desktop\java\python_django\16_LoggingAndProfiling\add_statistics\views.py changed, reloading.
Watching for file changes with StatReloader
Запрошена страница с корзиной пользователя
Internal Server Error: /statistics/full_rating/
Traceback (most recent call last):
  File "C:\Python39\lib\site-packages\django\core\handlers\exception.py", line 47, in inner
    response = get_response(request)
  File "C:\Python39\lib\site-packages\django\core\handlers\base.py", line 181, in _get_response
    response = wrapped_callback(request, *callback_args, **callback_kwargs)
  File "C:\Python39\lib\site-packages\django\views\generic\base.py", line 69, in view
    return self.dispatch(request, *args, **kwargs)
  File "C:\Python39\lib\site-packages\django\views\generic\base.py", line 101, in dispatch
    return handler(request, *args, **kwargs)
  File "C:\Users\11\Desktop\java\python_django\16_LoggingAndProfiling\add_statistics\views.py", line 99, in get
    self.extra_context = self.context_return(self.queryset)
  File "C:\Users\11\Desktop\java\python_django\16_LoggingAndProfiling\add_statistics\views.py", line 112, in context_return
    new_queryset = queryset.filter(product_name=product_name, status='y')
  File "C:\Python39\lib\site-packages\django\db\models\query.py", line 974, in filter
    return self._filter_or_exclude(False, args, kwargs)
  File "C:\Python39\lib\site-packages\django\db\models\query.py", line 986, in _filter_or_exclude
    raise TypeError('Cannot filter a query once a slice has been taken.')
TypeError: Cannot filter a query once a slice has been taken.
C:\Users\11\Desktop\java\python_django\16_LoggingAndProfiling\add_statistics\views.py changed, reloading.
Watching for file changes with StatReloader
Запрошена страница с корзиной пользователя
C:\Users\11\Desktop\java\python_django\16_LoggingAndProfiling\add_statistics\views.py changed, reloading.
Watching for file changes with StatReloader
C:\Users\11\Desktop\java\python_django\16_LoggingAndProfiling\add_statistics\views.py changed, reloading.
Watching for file changes with StatReloader
Запрошена страница с корзиной пользователя
C:\Users\11\Desktop\java\python_django\16_LoggingAndProfiling\add_statistics\views.py changed, reloading.
Watching for file changes with StatReloader
Запрошена страница с корзиной пользователя
Internal Server Error: /statistics/full_rating/
Traceback (most recent call last):
  File "C:\Python39\lib\site-packages\django\core\handlers\exception.py", line 47, in inner
    response = get_response(request)
  File "C:\Python39\lib\site-packages\django\core\handlers\base.py", line 181, in _get_response
    response = wrapped_callback(request, *callback_args, **callback_kwargs)
  File "C:\Python39\lib\site-packages\django\views\generic\base.py", line 69, in view
    return self.dispatch(request, *args, **kwargs)
  File "C:\Python39\lib\site-packages\django\views\generic\base.py", line 101, in dispatch
    return handler(request, *args, **kwargs)
  File "C:\Users\11\Desktop\java\python_django\16_LoggingAndProfiling\add_statistics\views.py", line 99, in get
    self.extra_context = self.context_return(self.queryset)
  File "C:\Users\11\Desktop\java\python_django\16_LoggingAndProfiling\add_statistics\views.py", line 112, in context_return
    new_queryset = queryset.filter(product_name=product_name)
  File "C:\Python39\lib\site-packages\django\db\models\query.py", line 974, in filter
    return self._filter_or_exclude(False, args, kwargs)
  File "C:\Python39\lib\site-packages\django\db\models\query.py", line 986, in _filter_or_exclude
    raise TypeError('Cannot filter a query once a slice has been taken.')
TypeError: Cannot filter a query once a slice has been taken.
C:\Users\11\Desktop\java\python_django\16_LoggingAndProfiling\add_statistics\views.py changed, reloading.
Watching for file changes with StatReloader
Запрошена страница с корзиной пользователя
C:\Users\11\Desktop\java\python_django\16_LoggingAndProfiling\add_statistics\views.py changed, reloading.
Watching for file changes with StatReloader
Запрошена страница с корзиной пользователя
Запрошена страница с корзиной пользователя
Запрошена страница с корзиной пользователя
C:\Users\11\Desktop\java\python_django\16_LoggingAndProfiling\market\views.py changed, reloading.
Watching for file changes with StatReloader
Запрошена страница с корзиной пользователя
Watching for file changes with StatReloader
Запрошена страница с корзиной пользователя
Not Found: /favicon.ico
Internal Server Error: /shops/basket
Traceback (most recent call last):
  File "C:\Python39\lib\site-packages\django\core\handlers\exception.py", line 47, in inner
    response = get_response(request)
  File "C:\Python39\lib\site-packages\django\core\handlers\base.py", line 181, in _get_response
    response = wrapped_callback(request, *callback_args, **callback_kwargs)
  File "C:\Python39\lib\site-packages\django\views\generic\base.py", line 69, in view
    return self.dispatch(request, *args, **kwargs)
  File "C:\Python39\lib\site-packages\django\views\generic\base.py", line 101, in dispatch
    return handler(request, *args, **kwargs)
  File "C:\Users\11\Desktop\java\python_django\16_LoggingAndProfiling\app_shops\views.py", line 165, in post
    print(dict(i.full_description))
ValueError: dictionary update sequence element #0 has length 1; 2 is required
C:\Users\11\Desktop\java\python_django\16_LoggingAndProfiling\app_shops\views.py changed, reloading.
Watching for file changes with StatReloader
Запрошена страница с корзиной пользователя
Watching for file changes with StatReloader
Запрошена страница с корзиной пользователя
Internal Server Error: /shops/basket
Traceback (most recent call last):
  File "C:\Python39\lib\site-packages\django\core\handlers\exception.py", line 47, in inner
    response = get_response(request)
  File "C:\Python39\lib\site-packages\django\core\handlers\base.py", line 181, in _get_response
    response = wrapped_callback(request, *callback_args, **callback_kwargs)
  File "C:\Python39\lib\site-packages\django\views\generic\base.py", line 69, in view
    return self.dispatch(request, *args, **kwargs)
  File "C:\Python39\lib\site-packages\django\views\generic\base.py", line 101, in dispatch
    return handler(request, *args, **kwargs)
  File "C:\Users\11\Desktop\java\python_django\16_LoggingAndProfiling\app_shops\views.py", line 165, in post
    print(str_in_dict(i.full_description))
  File "C:\Users\11\Desktop\java\python_django\16_LoggingAndProfiling\app_shops\views.py", line 297, in str_in_dict
    data_1 = dict(new_list[0] + '}')
ValueError: dictionary update sequence element #0 has length 1; 2 is required
C:\Users\11\Desktop\java\python_django\16_LoggingAndProfiling\app_shops\views.py changed, reloading.
Watching for file changes with StatReloader
C:\Users\11\Desktop\java\python_django\16_LoggingAndProfiling\app_shops\views.py changed, reloading.
Watching for file changes with StatReloader
Запрошена страница с корзиной пользователя
Internal Server Error: /shops/basket
Traceback (most recent call last):
  File "C:\Python39\lib\site-packages\django\core\handlers\exception.py", line 47, in inner
    response = get_response(request)
  File "C:\Python39\lib\site-packages\django\core\handlers\base.py", line 181, in _get_response
    response = wrapped_callback(request, *callback_args, **callback_kwargs)
  File "C:\Python39\lib\site-packages\django\views\generic\base.py", line 69, in view
    return self.dispatch(request, *args, **kwargs)
  File "C:\Python39\lib\site-packages\django\views\generic\base.py", line 101, in dispatch
    return handler(request, *args, **kwargs)
  File "C:\Users\11\Desktop\java\python_django\16_LoggingAndProfiling\app_shops\views.py", line 166, in post
    print(str_in_dict(i.full_description))
  File "C:\Users\11\Desktop\java\python_django\16_LoggingAndProfiling\app_shops\views.py", line 299, in str_in_dict
    data_2 = ast.literal_eval(new_list[1] + '{')
  File "C:\Python39\lib\ast.py", line 62, in literal_eval
    node_or_string = parse(node_or_string, mode='eval')
  File "C:\Python39\lib\ast.py", line 50, in parse
    return compile(source, filename, mode, flags,
  File "<unknown>", line 1
    'id': 33, 'name': 'TestShop2', 'description': 'TestText2TestText2TestText2TestText2TestText2', 'city': 'TestCity14', 'street': 'TestStreet12', 'house_number': 24, 'data_of_birth': None, 'phone': '+7800300798', 'email': 'TestShop2@mail.ru', 'purchases_count': 0, 'photo': 'default.jpg'}{
        ^
SyntaxError: invalid syntax
C:\Users\11\Desktop\java\python_django\16_LoggingAndProfiling\app_shops\views.py changed, reloading.
Watching for file changes with StatReloader
Запрошена страница с корзиной пользователя
C:\Users\11\Desktop\java\python_django\16_LoggingAndProfiling\app_shops\views.py changed, reloading.
Watching for file changes with StatReloader
Запрошена страница с корзиной пользователя
Watching for file changes with StatReloader
Запрошена страница с корзиной пользователя
Запрошена страница с корзиной пользователя
Internal Server Error: /shops/check
Traceback (most recent call last):
  File "C:\Python39\lib\site-packages\django\core\handlers\exception.py", line 47, in inner
    response = get_response(request)
  File "C:\Python39\lib\site-packages\django\core\handlers\base.py", line 188, in _get_response
    self.check_response(response, callback)
  File "C:\Python39\lib\site-packages\django\core\handlers\base.py", line 309, in check_response
    raise ValueError(
ValueError: The view app_shops.views.check_payment didn't return an HttpResponse object. It returned None instead.
Запрошена страница с корзиной пользователя
Internal Server Error: /shops/basket
Traceback (most recent call last):
  File "C:\Python39\lib\site-packages\django\core\handlers\exception.py", line 47, in inner
    response = get_response(request)
  File "C:\Python39\lib\site-packages\django\core\handlers\base.py", line 181, in _get_response
    response = wrapped_callback(request, *callback_args, **callback_kwargs)
  File "C:\Python39\lib\site-packages\django\views\generic\base.py", line 69, in view
    return self.dispatch(request, *args, **kwargs)
  File "C:\Python39\lib\site-packages\django\views\generic\base.py", line 101, in dispatch
    return handler(request, *args, **kwargs)
  File "C:\Users\11\Desktop\java\python_django\16_LoggingAndProfiling\app_shops\views.py", line 170, in post
    new_article = product_info['article'] + ',' + in_shop_info['id']
TypeError: can only concatenate str (not "int") to str
C:\Users\11\Desktop\java\python_django\16_LoggingAndProfiling\app_shops\views.py changed, reloading.
Watching for file changes with StatReloader
Запрошена страница с корзиной пользователя
Запрошена страница с корзиной пользователя
Watching for file changes with StatReloader
Запрошена страница с корзиной пользователя
Запрошена страница с корзиной пользователя
Internal Server Error: /shops/check
Traceback (most recent call last):
  File "C:\Python39\lib\site-packages\django\core\handlers\exception.py", line 47, in inner
    response = get_response(request)
  File "C:\Python39\lib\site-packages\django\core\handlers\base.py", line 181, in _get_response
    response = wrapped_callback(request, *callback_args, **callback_kwargs)
  File "C:\Users\11\Desktop\java\python_django\16_LoggingAndProfiling\app_shops\views.py", line 83, in check_payment
    UserBasket.objects.bulk_create(obj_list)
  File "C:\Python39\lib\site-packages\django\db\models\manager.py", line 85, in manager_method
    return getattr(self.get_queryset(), name)(*args, **kwargs)
  File "C:\Python39\lib\site-packages\django\db\models\query.py", line 503, in bulk_create
    self._prepare_for_bulk_create(objs)
  File "C:\Python39\lib\site-packages\django\db\models\query.py", line 462, in _prepare_for_bulk_create
    if obj.pk is None:
AttributeError: 'dict' object has no attribute 'pk'
C:\Users\11\Desktop\java\python_django\16_LoggingAndProfiling\app_shops\views.py changed, reloading.
Watching for file changes with StatReloader
Запрошена страница с корзиной пользователя
C:\Users\11\Desktop\java\python_django\16_LoggingAndProfiling\app_shops\views.py changed, reloading.
Watching for file changes with StatReloader
Запрошена страница с корзиной пользователя
Запрошена страница с корзиной пользователя
Internal Server Error: /shops/check
Traceback (most recent call last):
  File "C:\Python39\lib\site-packages\django\db\backends\utils.py", line 85, in _execute
    return self.cursor.execute(sql, params)
  File "C:\Python39\lib\site-packages\django\db\backends\sqlite3\base.py", line 416, in execute
    return Database.Cursor.execute(self, query, params)
sqlite3.IntegrityError: UNIQUE constraint failed: app_shops_userbasket.id

The above exception was the direct cause of the following exception:

Traceback (most recent call last):
  File "C:\Python39\lib\site-packages\django\core\handlers\exception.py", line 47, in inner
    response = get_response(request)
  File "C:\Python39\lib\site-packages\django\core\handlers\base.py", line 181, in _get_response
    response = wrapped_callback(request, *callback_args, **callback_kwargs)
  File "C:\Users\11\Desktop\java\python_django\16_LoggingAndProfiling\app_shops\views.py", line 84, in check_payment
    UserBasket.objects.bulk_create(obj_list)
  File "C:\Python39\lib\site-packages\django\db\models\manager.py", line 85, in manager_method
    return getattr(self.get_queryset(), name)(*args, **kwargs)
  File "C:\Python39\lib\site-packages\django\db\models\query.py", line 507, in bulk_create
    returned_columns = self._batched_insert(
  File "C:\Python39\lib\site-packages\django\db\models\query.py", line 1324, in _batched_insert
    self._insert(item, fields=fields, using=self.db, ignore_conflicts=ignore_conflicts)
  File "C:\Python39\lib\site-packages\django\db\models\query.py", line 1301, in _insert
    return query.get_compiler(using=using).execute_sql(returning_fields)
  File "C:\Python39\lib\site-packages\django\db\models\sql\compiler.py", line 1441, in execute_sql
    cursor.execute(sql, params)
  File "C:\Python39\lib\site-packages\debug_toolbar\panels\sql\tracking.py", line 205, in execute
    return self._record(self.cursor.execute, sql, params)
  File "C:\Python39\lib\site-packages\debug_toolbar\panels\sql\tracking.py", line 140, in _record
    return method(sql, params)
  File "C:\Python39\lib\site-packages\django\db\backends\utils.py", line 99, in execute
    return super().execute(sql, params)
  File "C:\Python39\lib\site-packages\django\db\backends\utils.py", line 67, in execute
    return self._execute_with_wrappers(sql, params, many=False, executor=self._execute)
  File "C:\Python39\lib\site-packages\django\db\backends\utils.py", line 76, in _execute_with_wrappers
    return executor(sql, params, many, context)
  File "C:\Python39\lib\site-packages\django\db\backends\utils.py", line 85, in _execute
    return self.cursor.execute(sql, params)
  File "C:\Python39\lib\site-packages\django\db\utils.py", line 90, in __exit__
    raise dj_exc_value.with_traceback(traceback) from exc_value
  File "C:\Python39\lib\site-packages\django\db\backends\utils.py", line 85, in _execute
    return self.cursor.execute(sql, params)
  File "C:\Python39\lib\site-packages\django\db\backends\sqlite3\base.py", line 416, in execute
    return Database.Cursor.execute(self, query, params)
django.db.utils.IntegrityError: UNIQUE constraint failed: app_shops_userbasket.id
C:\Users\11\Desktop\java\python_django\16_LoggingAndProfiling\app_shops\views.py changed, reloading.
Watching for file changes with StatReloader
Запрошена страница с корзиной пользователя
Запрошена страница с корзиной пользователя
Запрошена страница с корзиной пользователя
C:\Users\11\Desktop\java\python_django\16_LoggingAndProfiling\app_shops\views.py changed, reloading.
Watching for file changes with StatReloader
C:\Users\11\Desktop\java\python_django\16_LoggingAndProfiling\app_shops\views.py changed, reloading.
Watching for file changes with StatReloader
Watching for file changes with StatReloader
Запрошена страница с корзиной пользователя
Запрошена страница с корзиной пользователя
Запрошена страница с корзиной пользователя
Запрошена страница с корзиной пользователя
Запрошена страница с корзиной пользователя
Successfully imported extension module "markdown.extensions.toc".
Successfully loaded extension "markdown.extensions.toc.TocExtension".
Successfully imported extension module "markdown.extensions.toc".
Successfully loaded extension "markdown.extensions.toc.TocExtension".
C:\Users\11\Desktop\java\python_django\16_LoggingAndProfiling\site_api\api.py changed, reloading.
Watching for file changes with StatReloader
Successfully imported extension module "markdown.extensions.toc".
Successfully loaded extension "markdown.extensions.toc.TocExtension".
C:\Users\11\Desktop\java\python_django\16_LoggingAndProfiling\site_api\serializers.py changed, reloading.
Watching for file changes with StatReloader
Successfully imported extension module "markdown.extensions.toc".
Successfully loaded extension "markdown.extensions.toc.TocExtension".
Запрошена страница с корзиной пользователя
Запрошена страница с корзиной пользователя
Watching for file changes with StatReloader
Запрошена страница с корзиной пользователя
Запрошена страница с корзиной пользователя
C:\Users\11\Desktop\java\python_django\16_LoggingAndProfiling\app_users\views.py changed, reloading.
Watching for file changes with StatReloader
Запрошена страница с корзиной пользователя
C:\Users\11\Desktop\java\python_django\16_LoggingAndProfiling\app_users\views.py changed, reloading.
Watching for file changes with StatReloader
Запрошена страница с корзиной пользователя
C:\Users\11\Desktop\java\python_django\16_LoggingAndProfiling\app_users\views.py changed, reloading.
Watching for file changes with StatReloader
Запрошена страница с корзиной пользователя
C:\Users\11\Desktop\java\python_django\16_LoggingAndProfiling\app_users\views.py changed, reloading.
Watching for file changes with StatReloader
Запрошена страница с корзиной пользователя
Internal Server Error: /users/purchase_history/
Traceback (most recent call last):
  File "C:\Python39\lib\site-packages\django\template\defaulttags.py", line 974, in find_library
    return parser.libraries[name]
KeyError: 'media'

During handling of the above exception, another exception occurred:

Traceback (most recent call last):
  File "C:\Python39\lib\site-packages\django\core\handlers\exception.py", line 47, in inner
    response = get_response(request)
  File "C:\Python39\lib\site-packages\django\core\handlers\base.py", line 181, in _get_response
    response = wrapped_callback(request, *callback_args, **callback_kwargs)
  File "C:\Users\11\Desktop\java\python_django\16_LoggingAndProfiling\app_users\views.py", line 79, in purchase_history
    return render(request, 'app_users/purchase_history.html', context=extra_context)
  File "C:\Python39\lib\site-packages\django\shortcuts.py", line 19, in render
    content = loader.render_to_string(template_name, context, request, using=using)
  File "C:\Python39\lib\site-packages\django\template\loader.py", line 61, in render_to_string
    template = get_template(template_name, using=using)
  File "C:\Python39\lib\site-packages\django\template\loader.py", line 15, in get_template
    return engine.get_template(template_name)
  File "C:\Python39\lib\site-packages\django\template\backends\django.py", line 34, in get_template
    return Template(self.engine.get_template(template_name), self)
  File "C:\Python39\lib\site-packages\django\template\engine.py", line 163, in get_template
    template, origin = self.find_template(template_name)
  File "C:\Python39\lib\site-packages\django\template\engine.py", line 145, in find_template
    template = loader.get_template(name, skip=skip)
  File "C:\Python39\lib\site-packages\django\template\loaders\base.py", line 29, in get_template
    return Template(
  File "C:\Python39\lib\site-packages\django\template\base.py", line 155, in __init__
    self.nodelist = self.compile_nodelist()
  File "C:\Python39\lib\site-packages\django\template\base.py", line 199, in compile_nodelist
    return parser.parse()
  File "C:\Python39\lib\site-packages\django\template\base.py", line 508, in parse
    raise self.error(token, e)
  File "C:\Python39\lib\site-packages\django\template\base.py", line 506, in parse
    compiled_result = compile_func(self, token)
  File "C:\Python39\lib\site-packages\django\template\loader_tags.py", line 284, in do_extends
    nodelist = parser.parse()
  File "C:\Python39\lib\site-packages\django\template\base.py", line 508, in parse
    raise self.error(token, e)
  File "C:\Python39\lib\site-packages\django\template\base.py", line 506, in parse
    compiled_result = compile_func(self, token)
  File "C:\Python39\lib\site-packages\django\template\defaulttags.py", line 1031, in load
    lib = find_library(parser, name)
  File "C:\Python39\lib\site-packages\django\template\defaulttags.py", line 976, in find_library
    raise TemplateSyntaxError(
django.template.exceptions.TemplateSyntaxError: 'media' is not a registered tag library. Must be one of:
admin_list
admin_modify
admin_urls
cache
i18n
l10n
log
rest_framework
static
tz
C:\Users\11\Desktop\java\python_django\16_LoggingAndProfiling\market\settings.py changed, reloading.
Watching for file changes with StatReloader
Запрошена страница с корзиной пользователя
Internal Server Error: /users/purchase_history/
Traceback (most recent call last):
  File "C:\Python39\lib\site-packages\django\template\defaulttags.py", line 974, in find_library
    return parser.libraries[name]
KeyError: 'media'

During handling of the above exception, another exception occurred:

Traceback (most recent call last):
  File "C:\Python39\lib\site-packages\django\core\handlers\exception.py", line 47, in inner
    response = get_response(request)
  File "C:\Python39\lib\site-packages\django\core\handlers\base.py", line 181, in _get_response
    response = wrapped_callback(request, *callback_args, **callback_kwargs)
  File "C:\Users\11\Desktop\java\python_django\16_LoggingAndProfiling\app_users\views.py", line 79, in purchase_history
    return render(request, 'app_users/purchase_history.html', context=extra_context)
  File "C:\Python39\lib\site-packages\django\shortcuts.py", line 19, in render
    content = loader.render_to_string(template_name, context, request, using=using)
  File "C:\Python39\lib\site-packages\django\template\loader.py", line 61, in render_to_string
    template = get_template(template_name, using=using)
  File "C:\Python39\lib\site-packages\django\template\loader.py", line 15, in get_template
    return engine.get_template(template_name)
  File "C:\Python39\lib\site-packages\django\template\backends\django.py", line 34, in get_template
    return Template(self.engine.get_template(template_name), self)
  File "C:\Python39\lib\site-packages\django\template\engine.py", line 163, in get_template
    template, origin = self.find_template(template_name)
  File "C:\Python39\lib\site-packages\django\template\engine.py", line 145, in find_template
    template = loader.get_template(name, skip=skip)
  File "C:\Python39\lib\site-packages\django\template\loaders\base.py", line 29, in get_template
    return Template(
  File "C:\Python39\lib\site-packages\django\template\base.py", line 155, in __init__
    self.nodelist = self.compile_nodelist()
  File "C:\Python39\lib\site-packages\django\template\base.py", line 199, in compile_nodelist
    return parser.parse()
  File "C:\Python39\lib\site-packages\django\template\base.py", line 508, in parse
    raise self.error(token, e)
  File "C:\Python39\lib\site-packages\django\template\base.py", line 506, in parse
    compiled_result = compile_func(self, token)
  File "C:\Python39\lib\site-packages\django\template\loader_tags.py", line 284, in do_extends
    nodelist = parser.parse()
  File "C:\Python39\lib\site-packages\django\template\base.py", line 508, in parse
    raise self.error(token, e)
  File "C:\Python39\lib\site-packages\django\template\base.py", line 506, in parse
    compiled_result = compile_func(self, token)
  File "C:\Python39\lib\site-packages\django\template\defaulttags.py", line 1031, in load
    lib = find_library(parser, name)
  File "C:\Python39\lib\site-packages\django\template\defaulttags.py", line 976, in find_library
    raise TemplateSyntaxError(
django.template.exceptions.TemplateSyntaxError: 'media' is not a registered tag library. Must be one of:
admin_list
admin_modify
admin_urls
cache
i18n
l10n
log
rest_framework
static
tz
Watching for file changes with StatReloader
Запрошена страница с корзиной пользователя
Internal Server Error: /users/purchase_history/
Traceback (most recent call last):
  File "C:\Python39\lib\site-packages\django\template\base.py", line 500, in parse
    compile_func = self.tags[command]
KeyError: 'media'

During handling of the above exception, another exception occurred:

Traceback (most recent call last):
  File "C:\Python39\lib\site-packages\django\core\handlers\exception.py", line 47, in inner
    response = get_response(request)
  File "C:\Python39\lib\site-packages\django\core\handlers\base.py", line 181, in _get_response
    response = wrapped_callback(request, *callback_args, **callback_kwargs)
  File "C:\Users\11\Desktop\java\python_django\16_LoggingAndProfiling\app_users\views.py", line 79, in purchase_history
    return render(request, 'app_users/purchase_history.html', context=extra_context)
  File "C:\Python39\lib\site-packages\django\shortcuts.py", line 19, in render
    content = loader.render_to_string(template_name, context, request, using=using)
  File "C:\Python39\lib\site-packages\django\template\loader.py", line 61, in render_to_string
    template = get_template(template_name, using=using)
  File "C:\Python39\lib\site-packages\django\template\loader.py", line 15, in get_template
    return engine.get_template(template_name)
  File "C:\Python39\lib\site-packages\django\template\backends\django.py", line 34, in get_template
    return Template(self.engine.get_template(template_name), self)
  File "C:\Python39\lib\site-packages\django\template\engine.py", line 163, in get_template
    template, origin = self.find_template(template_name)
  File "C:\Python39\lib\site-packages\django\template\engine.py", line 145, in find_template
    template = loader.get_template(name, skip=skip)
  File "C:\Python39\lib\site-packages\django\template\loaders\base.py", line 29, in get_template
    return Template(
  File "C:\Python39\lib\site-packages\django\template\base.py", line 155, in __init__
    self.nodelist = self.compile_nodelist()
  File "C:\Python39\lib\site-packages\django\template\base.py", line 199, in compile_nodelist
    return parser.parse()
  File "C:\Python39\lib\site-packages\django\template\base.py", line 508, in parse
    raise self.error(token, e)
  File "C:\Python39\lib\site-packages\django\template\base.py", line 506, in parse
    compiled_result = compile_func(self, token)
  File "C:\Python39\lib\site-packages\django\template\loader_tags.py", line 284, in do_extends
    nodelist = parser.parse()
  File "C:\Python39\lib\site-packages\django\template\base.py", line 508, in parse
    raise self.error(token, e)
  File "C:\Python39\lib\site-packages\django\template\base.py", line 506, in parse
    compiled_result = compile_func(self, token)
  File "C:\Python39\lib\site-packages\django\template\loader_tags.py", line 222, in do_block
    nodelist = parser.parse(('endblock',))
  File "C:\Python39\lib\site-packages\django\template\base.py", line 508, in parse
    raise self.error(token, e)
  File "C:\Python39\lib\site-packages\django\template\base.py", line 506, in parse
    compiled_result = compile_func(self, token)
  File "C:\Python39\lib\site-packages\django\template\defaulttags.py", line 810, in do_for
    nodelist_loop = parser.parse(('empty', 'endfor',))
  File "C:\Python39\lib\site-packages\django\template\base.py", line 502, in parse
    self.invalid_block_tag(token, command, parse_until)
  File "C:\Python39\lib\site-packages\django\template\base.py", line 552, in invalid_block_tag
    raise self.error(
django.template.exceptions.TemplateSyntaxError: Invalid block tag on line 24: 'media', expected 'empty' or 'endfor'. Did you forget to register or load this tag?
Запрошена страница с корзиной пользователя
Internal Server Error: /users/purchase_history/
Traceback (most recent call last):
  File "C:\Python39\lib\site-packages\django\template\defaulttags.py", line 974, in find_library
    return parser.libraries[name]
KeyError: 'media'

During handling of the above exception, another exception occurred:

Traceback (most recent call last):
  File "C:\Python39\lib\site-packages\django\core\handlers\exception.py", line 47, in inner
    response = get_response(request)
  File "C:\Python39\lib\site-packages\django\core\handlers\base.py", line 181, in _get_response
    response = wrapped_callback(request, *callback_args, **callback_kwargs)
  File "C:\Users\11\Desktop\java\python_django\16_LoggingAndProfiling\app_users\views.py", line 79, in purchase_history
    return render(request, 'app_users/purchase_history.html', context=extra_context)
  File "C:\Python39\lib\site-packages\django\shortcuts.py", line 19, in render
    content = loader.render_to_string(template_name, context, request, using=using)
  File "C:\Python39\lib\site-packages\django\template\loader.py", line 62, in render_to_string
    return template.render(context, request)
  File "C:\Python39\lib\site-packages\django\template\backends\django.py", line 61, in render
    return self.template.render(context)
  File "C:\Python39\lib\site-packages\django\template\base.py", line 176, in render
    return self._render(context)
  File "C:\Python39\lib\site-packages\django\test\utils.py", line 101, in instrumented_test_render
    return self.nodelist.render(context)
  File "C:\Python39\lib\site-packages\django\template\base.py", line 977, in render
    return SafeString(''.join([
  File "C:\Python39\lib\site-packages\django\template\base.py", line 978, in <listcomp>
    node.render_annotated(context) for node in self
  File "C:\Python39\lib\site-packages\django\template\base.py", line 938, in render_annotated
    return self.render(context)
  File "C:\Python39\lib\site-packages\django\template\loader_tags.py", line 130, in render
    compiled_parent = self.get_parent(context)
  File "C:\Python39\lib\site-packages\django\template\loader_tags.py", line 127, in get_parent
    return self.find_template(parent, context)
  File "C:\Python39\lib\site-packages\django\template\loader_tags.py", line 106, in find_template
    template, origin = context.template.engine.find_template(
  File "C:\Python39\lib\site-packages\django\template\engine.py", line 145, in find_template
    template = loader.get_template(name, skip=skip)
  File "C:\Python39\lib\site-packages\django\template\loaders\base.py", line 29, in get_template
    return Template(
  File "C:\Python39\lib\site-packages\django\template\base.py", line 155, in __init__
    self.nodelist = self.compile_nodelist()
  File "C:\Python39\lib\site-packages\django\template\base.py", line 199, in compile_nodelist
    return parser.parse()
  File "C:\Python39\lib\site-packages\django\template\base.py", line 508, in parse
    raise self.error(token, e)
  File "C:\Python39\lib\site-packages\django\template\base.py", line 506, in parse
    compiled_result = compile_func(self, token)
  File "C:\Python39\lib\site-packages\django\template\defaulttags.py", line 1031, in load
    lib = find_library(parser, name)
  File "C:\Python39\lib\site-packages\django\template\defaulttags.py", line 976, in find_library
    raise TemplateSyntaxError(
django.template.exceptions.TemplateSyntaxError: 'media' is not a registered tag library. Must be one of:
admin_list
admin_modify
admin_urls
cache
i18n
l10n
log
rest_framework
static
tz
Запрошена страница с корзиной пользователя
Запрошена страница с корзиной пользователя
Internal Server Error: /shops/basket
Traceback (most recent call last):
  File "C:\Python39\lib\site-packages\django\core\handlers\exception.py", line 47, in inner
    response = get_response(request)
  File "C:\Python39\lib\site-packages\django\core\handlers\base.py", line 181, in _get_response
    response = wrapped_callback(request, *callback_args, **callback_kwargs)
  File "C:\Python39\lib\site-packages\django\views\generic\base.py", line 69, in view
    return self.dispatch(request, *args, **kwargs)
  File "C:\Python39\lib\site-packages\django\views\generic\base.py", line 101, in dispatch
    return handler(request, *args, **kwargs)
  File "C:\Users\11\Desktop\java\python_django\16_LoggingAndProfiling\app_shops\views.py", line 172, in post
    product_shop_list = str_in_dict(i.full_description)
  File "C:\Users\11\Desktop\java\python_django\16_LoggingAndProfiling\app_shops\views.py", line 308, in str_in_dict
    data_2 = ast.literal_eval('{' + new_list[1])
  File "C:\Python39\lib\ast.py", line 105, in literal_eval
    return _convert(node_or_string)
  File "C:\Python39\lib\ast.py", line 94, in _convert
    return dict(zip(map(_convert, node.keys),
  File "C:\Python39\lib\ast.py", line 104, in _convert
    return _convert_signed_num(node)
  File "C:\Python39\lib\ast.py", line 78, in _convert_signed_num
    return _convert_num(node)
  File "C:\Python39\lib\ast.py", line 69, in _convert_num
    _raise_malformed_node(node)
  File "C:\Python39\lib\ast.py", line 66, in _raise_malformed_node
    raise ValueError(f'malformed node or string: {node!r}')
ValueError: malformed node or string: <ast.Call object at 0x000002938613EA30>
tag: Orientation (274) - type: short (3) - value: b'\x00\x01'
tag: XResolution (282) - type: rational (5) Tag Location: 34 - Data Location: 74 - value: b'\x00\x00\x00\xe1\x00\x00\x00\x01'
tag: YResolution (283) - type: rational (5) Tag Location: 46 - Data Location: 82 - value: b'\x00\x00\x00\xe1\x00\x00\x00\x01'
tag: ResolutionUnit (296) - type: short (3) - value: b'\x00\x02'
tag: ExifIFD (34665) - type: long (4) - value: b'\x00\x00\x00Z'
Importing BlpImagePlugin
Importing BmpImagePlugin
Importing BufrStubImagePlugin
Importing CurImagePlugin
Importing DcxImagePlugin
Importing DdsImagePlugin
Importing EpsImagePlugin
Importing FitsStubImagePlugin
Importing FliImagePlugin
Importing FpxImagePlugin
Image: failed to import FpxImagePlugin: No module named 'olefile'
Importing FtexImagePlugin
Importing GbrImagePlugin
Importing GifImagePlugin
Importing GribStubImagePlugin
Importing Hdf5StubImagePlugin
Importing IcnsImagePlugin
Importing IcoImagePlugin
Importing ImImagePlugin
Importing ImtImagePlugin
Importing IptcImagePlugin
Importing JpegImagePlugin
Importing Jpeg2KImagePlugin
Importing McIdasImagePlugin
Importing MicImagePlugin
Image: failed to import MicImagePlugin: No module named 'olefile'
Importing MpegImagePlugin
Importing MpoImagePlugin
Importing MspImagePlugin
Importing PalmImagePlugin
Importing PcdImagePlugin
Importing PcxImagePlugin
Importing PdfImagePlugin
Importing PixarImagePlugin
Importing PngImagePlugin
Importing PpmImagePlugin
Importing PsdImagePlugin
Importing SgiImagePlugin
Importing SpiderImagePlugin
Importing SunImagePlugin
Importing TgaImagePlugin
Importing TiffImagePlugin
Importing WebPImagePlugin
Importing WmfImagePlugin
Importing XbmImagePlugin
Importing XpmImagePlugin
Importing XVThumbImagePlugin
Internal Server Error: /admin/app_shops/productprofile/
Traceback (most recent call last):
  File "C:\Python39\lib\site-packages\django\core\handlers\exception.py", line 47, in inner
    response = get_response(request)
  File "C:\Python39\lib\site-packages\django\core\handlers\base.py", line 181, in _get_response
    response = wrapped_callback(request, *callback_args, **callback_kwargs)
  File "C:\Python39\lib\site-packages\django\contrib\admin\options.py", line 622, in wrapper
    return self.admin_site.admin_view(view)(*args, **kwargs)
  File "C:\Python39\lib\site-packages\django\utils\decorators.py", line 130, in _wrapped_view
    response = view_func(request, *args, **kwargs)
  File "C:\Python39\lib\site-packages\django\views\decorators\cache.py", line 57, in _wrapped_view_func
    response = view_func(request, *args, **kwargs)
  File "C:\Python39\lib\site-packages\django\contrib\admin\sites.py", line 236, in inner
    return view(request, *args, **kwargs)
  File "C:\Python39\lib\site-packages\django\utils\decorators.py", line 43, in _wrapper
    return bound_method(*args, **kwargs)
  File "C:\Python39\lib\site-packages\django\utils\decorators.py", line 130, in _wrapped_view
    response = view_func(request, *args, **kwargs)
  File "C:\Python39\lib\site-packages\django\contrib\admin\options.py", line 1710, in changelist_view
    cl = self.get_changelist_instance(request)
  File "C:\Python39\lib\site-packages\django\contrib\admin\options.py", line 742, in get_changelist_instance
    return ChangeList(
  File "C:\Python39\lib\site-packages\django\contrib\admin\views\main.py", line 100, in __init__
    self.queryset = self.get_queryset(request)
  File "C:\Python39\lib\site-packages\django\contrib\admin\views\main.py", line 486, in get_queryset
    qs, search_may_have_duplicates = self.model_admin.get_search_results(
  File "C:\Python39\lib\site-packages\django\contrib\admin\options.py", line 1041, in get_search_results
    queryset = queryset.filter(or_queries)
  File "C:\Python39\lib\site-packages\django\db\models\query.py", line 974, in filter
    return self._filter_or_exclude(False, args, kwargs)
  File "C:\Python39\lib\site-packages\django\db\models\query.py", line 992, in _filter_or_exclude
    clone._filter_or_exclude_inplace(negate, args, kwargs)
  File "C:\Python39\lib\site-packages\django\db\models\query.py", line 999, in _filter_or_exclude_inplace
    self._query.add_q(Q(*args, **kwargs))
  File "C:\Python39\lib\site-packages\django\db\models\sql\query.py", line 1375, in add_q
    clause, _ = self._add_q(q_object, self.used_aliases)
  File "C:\Python39\lib\site-packages\django\db\models\sql\query.py", line 1396, in _add_q
    child_clause, needed_inner = self.build_filter(
  File "C:\Python39\lib\site-packages\django\db\models\sql\query.py", line 1252, in build_filter
    return self._add_q(
  File "C:\Python39\lib\site-packages\django\db\models\sql\query.py", line 1396, in _add_q
    child_clause, needed_inner = self.build_filter(
  File "C:\Python39\lib\site-packages\django\db\models\sql\query.py", line 1329, in build_filter
    condition = self.build_lookup(lookups, col, value)
  File "C:\Python39\lib\site-packages\django\db\models\sql\query.py", line 1171, in build_lookup
    raise FieldError('Related Field got invalid lookup: {}'.format(lookup_name))
django.core.exceptions.FieldError: Related Field got invalid lookup: icontains
Internal Server Error: /shops/basket
Traceback (most recent call last):
  File "C:\Python39\lib\site-packages\django\core\handlers\exception.py", line 47, in inner
    response = get_response(request)
  File "C:\Python39\lib\site-packages\django\core\handlers\base.py", line 181, in _get_response
    response = wrapped_callback(request, *callback_args, **callback_kwargs)
  File "C:\Python39\lib\site-packages\django\views\generic\base.py", line 69, in view
    return self.dispatch(request, *args, **kwargs)
  File "C:\Python39\lib\site-packages\django\views\generic\base.py", line 101, in dispatch
    return handler(request, *args, **kwargs)
  File "C:\Users\11\Desktop\java\python_django\16_LoggingAndProfiling\app_shops\views.py", line 172, in post
    product_shop_list = str_in_dict(i.full_description)
  File "C:\Users\11\Desktop\java\python_django\16_LoggingAndProfiling\app_shops\views.py", line 308, in str_in_dict
    data_2 = ast.literal_eval('{' + new_list[1])
  File "C:\Python39\lib\ast.py", line 105, in literal_eval
    return _convert(node_or_string)
  File "C:\Python39\lib\ast.py", line 94, in _convert
    return dict(zip(map(_convert, node.keys),
  File "C:\Python39\lib\ast.py", line 104, in _convert
    return _convert_signed_num(node)
  File "C:\Python39\lib\ast.py", line 78, in _convert_signed_num
    return _convert_num(node)
  File "C:\Python39\lib\ast.py", line 69, in _convert_num
    _raise_malformed_node(node)
  File "C:\Python39\lib\ast.py", line 66, in _raise_malformed_node
    raise ValueError(f'malformed node or string: {node!r}')
ValueError: malformed node or string: <ast.Call object at 0x0000029389252AF0>
Internal Server Error: /shops/basket
Traceback (most recent call last):
  File "C:\Python39\lib\site-packages\django\core\handlers\exception.py", line 47, in inner
    response = get_response(request)
  File "C:\Python39\lib\site-packages\django\core\handlers\base.py", line 181, in _get_response
    response = wrapped_callback(request, *callback_args, **callback_kwargs)
  File "C:\Python39\lib\site-packages\django\views\generic\base.py", line 69, in view
    return self.dispatch(request, *args, **kwargs)
  File "C:\Python39\lib\site-packages\django\views\generic\base.py", line 101, in dispatch
    return handler(request, *args, **kwargs)
  File "C:\Users\11\Desktop\java\python_django\16_LoggingAndProfiling\app_shops\views.py", line 172, in post
    product_shop_list = str_in_dict(i.full_description)
  File "C:\Users\11\Desktop\java\python_django\16_LoggingAndProfiling\app_shops\views.py", line 308, in str_in_dict
    data_2 = ast.literal_eval('{' + new_list[1])
  File "C:\Python39\lib\ast.py", line 105, in literal_eval
    return _convert(node_or_string)
  File "C:\Python39\lib\ast.py", line 94, in _convert
    return dict(zip(map(_convert, node.keys),
  File "C:\Python39\lib\ast.py", line 104, in _convert
    return _convert_signed_num(node)
  File "C:\Python39\lib\ast.py", line 78, in _convert_signed_num
    return _convert_num(node)
  File "C:\Python39\lib\ast.py", line 69, in _convert_num
    _raise_malformed_node(node)
  File "C:\Python39\lib\ast.py", line 66, in _raise_malformed_node
    raise ValueError(f'malformed node or string: {node!r}')
ValueError: malformed node or string: <ast.Call object at 0x0000029384AC92B0>
Запрошена страница с корзиной пользователя
Internal Server Error: /shops/basket
Traceback (most recent call last):
  File "C:\Python39\lib\site-packages\django\core\handlers\exception.py", line 47, in inner
    response = get_response(request)
  File "C:\Python39\lib\site-packages\django\core\handlers\base.py", line 181, in _get_response
    response = wrapped_callback(request, *callback_args, **callback_kwargs)
  File "C:\Python39\lib\site-packages\django\views\generic\base.py", line 69, in view
    return self.dispatch(request, *args, **kwargs)
  File "C:\Python39\lib\site-packages\django\views\generic\base.py", line 101, in dispatch
    return handler(request, *args, **kwargs)
  File "C:\Users\11\Desktop\java\python_django\16_LoggingAndProfiling\app_shops\views.py", line 172, in post
    product_shop_list = str_in_dict(i.full_description)
  File "C:\Users\11\Desktop\java\python_django\16_LoggingAndProfiling\app_shops\views.py", line 308, in str_in_dict
    data_2 = ast.literal_eval('{' + new_list[1])
  File "C:\Python39\lib\ast.py", line 105, in literal_eval
    return _convert(node_or_string)
  File "C:\Python39\lib\ast.py", line 94, in _convert
    return dict(zip(map(_convert, node.keys),
  File "C:\Python39\lib\ast.py", line 104, in _convert
    return _convert_signed_num(node)
  File "C:\Python39\lib\ast.py", line 78, in _convert_signed_num
    return _convert_num(node)
  File "C:\Python39\lib\ast.py", line 69, in _convert_num
    _raise_malformed_node(node)
  File "C:\Python39\lib\ast.py", line 66, in _raise_malformed_node
    raise ValueError(f'malformed node or string: {node!r}')
ValueError: malformed node or string: <ast.Call object at 0x0000029386830760>
Watching for file changes with StatReloader
Запрошена страница с корзиной пользователя
Internal Server Error: /shops/basket
Traceback (most recent call last):
  File "C:\Python39\lib\site-packages\django\core\handlers\exception.py", line 47, in inner
    response = get_response(request)
  File "C:\Python39\lib\site-packages\django\core\handlers\base.py", line 181, in _get_response
    response = wrapped_callback(request, *callback_args, **callback_kwargs)
  File "C:\Python39\lib\site-packages\django\views\generic\base.py", line 69, in view
    return self.dispatch(request, *args, **kwargs)
  File "C:\Python39\lib\site-packages\django\views\generic\base.py", line 101, in dispatch
    return handler(request, *args, **kwargs)
  File "C:\Users\11\Desktop\java\python_django\16_LoggingAndProfiling\app_shops\views.py", line 172, in post
    product_shop_list = str_in_dict(i.full_description)
  File "C:\Users\11\Desktop\java\python_django\16_LoggingAndProfiling\app_shops\views.py", line 310, in str_in_dict
    data_2 = ast.literal_eval('{' + new_list[1])
  File "C:\Python39\lib\ast.py", line 62, in literal_eval
    node_or_string = parse(node_or_string, mode='eval')
  File "C:\Python39\lib\ast.py", line 50, in parse
    return compile(source, filename, mode, flags,
  File "<unknown>", line 1
    {'id': 32, 'name': 'TestShop1', 'description': 'TestText1TestText1TestText1TestText1TestText1', 'city': 'TestCity11', 'street': 'TestStreet1', 'house_number': 24, 'data_of_birth': None, 'phone': '+7800300601', 'email': 'TestShop1@mail.ru', 'purchases_count': 0, 'photo': 'date'{'id': 82, 'article': '1013', 'category_id': 6, 'name': 'TestProduct1907', 'description': 'TestText13TestText13TestText13TestText13TestText13', 'price': 4942.0, 'photo': 'product_photo/ёлка.jpg', 'amount': 7055
                                                                                                                                                                                                                                                                                         ^
SyntaxError: invalid syntax
Watching for file changes with StatReloader
Запрошена страница с корзиной пользователя
Not Found: /favicon.ico
Запрошена страница с корзиной пользователя
Internal Server Error: /shops/basket
Traceback (most recent call last):
  File "C:\Python39\lib\site-packages\django\core\handlers\exception.py", line 47, in inner
    response = get_response(request)
  File "C:\Python39\lib\site-packages\django\core\handlers\base.py", line 181, in _get_response
    response = wrapped_callback(request, *callback_args, **callback_kwargs)
  File "C:\Python39\lib\site-packages\django\views\generic\base.py", line 69, in view
    return self.dispatch(request, *args, **kwargs)
  File "C:\Python39\lib\site-packages\django\views\generic\base.py", line 101, in dispatch
    return handler(request, *args, **kwargs)
  File "C:\Users\11\Desktop\java\python_django\16_LoggingAndProfiling\app_shops\views.py", line 176, in post
    new_article = product_info['article'] + ',' + str(in_shop_info['id'])
KeyError: 'article'
C:\Users\11\Desktop\java\python_django\16_LoggingAndProfiling\app_shops\views.py changed, reloading.
Watching for file changes with StatReloader
Запрошена страница с корзиной пользователя
Запрошена страница с корзиной пользователя
Запрошена страница с корзиной пользователя
Not Found: /users/purchase_history/product_photo/ёлка.jpg
Запрошена страница с корзиной пользователя
C:\Users\11\Desktop\java\python_django\16_LoggingAndProfiling\app_users\views.py changed, reloading.
Watching for file changes with StatReloader
C:\Users\11\Desktop\java\python_django\16_LoggingAndProfiling\add_statistics\views.py changed, reloading.
Watching for file changes with StatReloader
Watching for file changes with StatReloader
Not Found: /media/
Not Found: /media/
Not Found: /media/
Запрошена страница с корзиной пользователя
Not Found: /media/
Not Found: /media/
Запрошена страница с корзиной пользователя
Запрошена страница с корзиной пользователя
Запрошена страница с корзиной пользователя
C:\Users\11\Desktop\java\python_django\16_LoggingAndProfiling\app_users\views.py changed, reloading.
Watching for file changes with StatReloader
Watching for file changes with StatReloader
Запрошена страница с корзиной пользователя
Запрошена страница с корзиной пользователя
Потльзовотель: pavlove, пополнил баланс до: F(purchases_count) + Value(1000)
Запрошена страница с корзиной пользователя
C:\Users\11\Desktop\java\python_django\16_LoggingAndProfiling\app_users\admin.py changed, reloading.
Watching for file changes with StatReloader
C:\Users\11\Desktop\java\python_django\16_LoggingAndProfiling\app_shops\views.py changed, reloading.
Watching for file changes with StatReloader
Запрошена страница с корзиной пользователя
Запрошена страница с корзиной пользователя
Internal Server Error: /shops/check
Traceback (most recent call last):
  File "C:\Python39\lib\site-packages\django\core\handlers\exception.py", line 47, in inner
    response = get_response(request)
  File "C:\Python39\lib\site-packages\django\core\handlers\base.py", line 181, in _get_response
    response = wrapped_callback(request, *callback_args, **callback_kwargs)
  File "C:\Users\11\Desktop\java\python_django\16_LoggingAndProfiling\app_shops\views.py", line 70, in check_payment
    new_status = user_status(extra_context['user_profile'].full_sum_count)
  File "C:\Users\11\Desktop\java\python_django\16_LoggingAndProfiling\app_users\views.py", line 354, in user_status
    if full_sum < 10000:
TypeError: '<' not supported between instances of 'CombinedExpression' and 'int'
C:\Users\11\Desktop\java\python_django\16_LoggingAndProfiling\app_shops\views.py changed, reloading.
Watching for file changes with StatReloader
Запрошена страница с корзиной пользователя
Internal Server Error: /shops/check
Traceback (most recent call last):
  File "C:\Python39\lib\site-packages\django\core\handlers\exception.py", line 47, in inner
    response = get_response(request)
  File "C:\Python39\lib\site-packages\django\core\handlers\base.py", line 181, in _get_response
    response = wrapped_callback(request, *callback_args, **callback_kwargs)
  File "C:\Users\11\Desktop\java\python_django\16_LoggingAndProfiling\app_shops\views.py", line 71, in check_payment
    new_status = user_status(extra_context['user_profile'].full_sum_count)
  File "C:\Users\11\Desktop\java\python_django\16_LoggingAndProfiling\app_users\views.py", line 354, in user_status
    if full_sum < 10000:
TypeError: '<' not supported between instances of 'CombinedExpression' and 'int'
Watching for file changes with StatReloader
Запрошена страница с корзиной пользователя
C:\Users\11\Desktop\java\python_django\16_LoggingAndProfiling\app_users\models.py changed, reloading.
Watching for file changes with StatReloader
C:\Users\11\Desktop\java\python_django\16_LoggingAndProfiling\app_shops\views.py changed, reloading.
Watching for file changes with StatReloader
C:\Users\11\Desktop\java\python_django\16_LoggingAndProfiling\app_shops\views.py changed, reloading.
Watching for file changes with StatReloader
